Workbook
Name a: #REF!
Name a_1: #REF!
Name b: #REF!
Name a: #REF!
Name a_1: #REF!
Name b: #REF!
Name a: '[1]BOM '!#REF!
Name a_1: #REF!
Name b: #REF!

Sheet Quotation Rig Adaptor
B1: Quotations | E1: Assy No. | F1: =IFERROR('Summary RIG ADAPTOR'!B3, "")
B2: =IFERROR('Summary RIG ADAPTOR'!B2, "") | E2: MOQ Qty | F2: =IFERROR('Summary RIG ADAPTOR'!F3, "")
B3: A. | C3: RM Cost | E3: Weight in Kg. | F3: Price in INR
B4: i. | C4: RM Gross Weight | E4: =IFERROR('Summary RIG ADAPTOR'!G8, "")
B5: ii. | C5: RM Net Weight | E5: =IFERROR('Summary RIG ADAPTOR'!G9, "")
B6: iii. | C6: Raw Material | F6: =IFERROR('Summary RIG ADAPTOR'!G13, "")
B7: iv. | C7: BOP + Fastener | F7: =IFERROR('Summary RIG ADAPTOR'!F19, "")
C8: TOTAL RM COST | F8: =IFERROR(SUM(F6:F7), "")
E9: =IFERROR((E4-E5)/E4, "")
B10: B. | C10: Process Cost
B11: i. | C11: Assy Cost | D11: 0 | F11: =IFERROR(D11*E5, "")
B12: ii. | C12: Fabrication / Process Cost | D12: 0 | F12: =IFERROR('Summary RIG ADAPTOR'!F33, "")
B13: iii. | C13: Inspection and Testing | D13: 8 | F13: =IFERROR($D$13*E5, "")
B14: iv. | C14: Painting | D14: 10 | F14: =IFERROR($D$14*E5, "")
B15: v | C15: Packaging | D15: Customer Scope | F15: 0
C16: TOTAL BASIC COST | F16: =IFERROR(SUM(F8:F15), "")
B18: C. | C18: Fixed Cost
B19: i | C19: ICC Cost | D19: 0.01 | F19: =IFERROR(F22*$D$19, "")
B20: ii | C20: Rejection | D20: 0.015 | F20: =IFERROR(F22*$D$20, "")
B21: iii | C21: Transportation | D21: Ex-works | F21: 0
C22: Sub Total | F22: =IFERROR(SUM(F19:F21)+F16, "")
B24: D. | C24: Variable Cost
B25: i | C25: Contingency / Warranty | D25: 0.01 | F25: =IFERROR(F28*$D$25, "")
B26: ii | C26: Overheads | D26: 0.08 | F26: =IFERROR(F28*$D$26, "")
B27: iii | C27: Contribution / Profit | D27: 0.1 | F27: =IFERROR(F28*$D$27, "") | H27: Per kg cost | I27: Internal Cost | J27: Margin%
C28: Total Price for x Parts | E28: =IFERROR(F2, "") | F28: =IFERROR(SUM(F22:F27), "") | H28: =IFERROR(F28/E5, "") | I28: =IFERROR('Summary RIG ADAPTOR'!F36, "") | J28: =IFERROR((F28-I28)/F28, "")
C29: Total Price Per Part | E29: 1 | F29: =IFERROR(F28/E28, "")
B32: NON-RECURRING COST | E32: Assy No, | F32: =IFERROR(F1, "")
B33: E. | C33: ENGINEERING CHARGES | F33: =IFERROR('Summary RIG ADAPTOR'!F41, "")
B34: F. | C34: DEVELOPMENT OF JIG AND FIXTURES (01 time) | F34: =IFERROR('Summary RIG ADAPTOR'!F42, "")
C35: Sub Cost | F35: =IFERROR(SUM(F33:F34), "")
B36: i | C36: Contingency | D36: 0.02 | F36: =IFERROR(F39*$D$36, "")
B37: ii | C37: Overheads | D37: 0.08 | F37: =IFERROR(F39*$D$37, "")
B38: iii | C38: Contribution / Profit | D38: 0.113 | F38: =IFERROR(F39*$D$38, "") | H38: Per kg cost | I38: Internal Cost | J38: Margin%
C39: Total NRC Cost | E39: 1 | F39: =IFERROR(SUM(F35:F38), "") | H39: =IFERROR(F39/E5, "") | I39: =IFERROR('Summary RIG ADAPTOR'!F43, "") | J39: =IFERROR((F39-I39)/F39, "")

Sheet Summary RIG ADAPTOR
A1: RC COSTING SHEET
A2: PRODUCT NAME:- | B2: =IFERROR('BOM RIG ADAPTOR'!E3, "") | E2: RFQ Ref. | Y2: As per spec STD000910-4.3 | AD2: Akzonobel/Jotun
A3: ITEM DRG NO | B3: =IFERROR('BOM RIG ADAPTOR'!C3, "") | E3: MOQ | F3: =IFERROR('BOM RIG ADAPTOR'!F3, "") | AC3: Total Area | AD3: =IFERROR('BOM RIG ADAPTOR'!AC3, "") | AF3: SQM | AG3: As per drawing
A4: Total Net WT as per Drawing | B4: =IFERROR('BOM RIG ADAPTOR'!H3, "") | Y4: Paint Details | Z4: DFT | AA4: Tho. Coverage (Area m2) | AB4: Wastage factor | AC4: Actual Coverage (Area m2) | AD4: Req Paint (Litre) | AE4: MOQ Qty. | AF4: Rate of paint | AG4: Actual Amount | AH4: MOQ Amount
A5: COSTBREAKUP OF COMPONENT (QTY-01 No.) | X5: Primer | Y5: Intergard 345 | Z5: 150 | AA5: =IFERROR(125*5.6/Z5, "") | AB5: 0.55 | AC5: =IFERROR(AA5*(100%-AB5), "") | AD5: =IFERROR((1/AC5)*$AD$3, "") | AE5: 20 | AF5: 1000 | AG5: =IFERROR(AF5*AD5, "") | AH5: =IFERROR(AF5*AE5, "")
A6: RAW MATERIAL COST | K6: S.No | L6: Profile | M6: Size (mm) | N6: Material | O6: Net weight kg | P6: Gross Weight kg | Q6: MOQ Weight | R6: Cal. Gross Wt | S6: Scrap % | X6: Paint | Y6: Interthane 990 (Ral 9016) | Z6: 75 | AA6: =IFERROR(50*11.4/Z6, "") | AB6: 0.55 | AC6: =IFERROR(AA6*(100%-AB6), "") | AD6: =IFERROR((1/AC6)*$AD$3, "") | AE6: 20 | AF6: 800 | AG6: =IFERROR(AF6*AD6, "") | AH6: =IFERROR(AF6*AE6, "")
A7: SPEC | D7: =IFERROR(N7, "") | E7: IS2062: E250A Block | F7: IS2062: E250A Plate | K7: 1 | L7: Pipe | M7: OD 355.6 x 19.05 thk | N7: ASTM A106 GR.B | O7: =IFERROR('BOM RIG ADAPTOR'!I4, "") | P7: =IFERROR('BOM RIG ADAPTOR'!O4, "") | Q7: =IFERROR(158.11*6, "") | R7: =IFERROR(IF(Q7>P7,Q7,IF(Q7<P7,P7)), "") | S7: =IFERROR((R7-O7)/R7, "") | X7: Thinner | AD7: =IFERROR(SUM(AD5:AD6)*0.3, "") | AE7: 20 | AF7: 200 | AG7: =IFERROR(AF7*AD7, "") | AH7: =IFERROR(AF7*AE7, "")
A8: GROSS WT. (KG) | D8: =IFERROR(R7, "") | E8: =IFERROR(R8, "") | F8: =IFERROR(SUM(R9:R12), "") | G8: =IFERROR(SUM(B8:F8), "") | K8: 2 | L8: Block | M8: 180 | N8: IS2062: E250A | O8: =IFERROR('BOM RIG ADAPTOR'!I5, "") | P8: =IFERROR('BOM RIG ADAPTOR'!O5, "") | Q8: =IFERROR(M8*1500*3000*0.00000785*1/8, "") | R8: =IFERROR(IF(Q8>P8,Q8,IF(Q8<P8,P8)), "") | S8: =IFERROR((R8-O8)/R8, "") | X8: Total | AD8: =IFERROR(SUM(AD5:AD7), "") | AG8: =IFERROR(SUM(AG5:AG7), "") | AH8: =IFERROR(SUM(AH5:AH7), "")
A9: NET WT (KG) | D9: =IFERROR(O7, "") | E9: =IFERROR(O8, "") | F9: =IFERROR(SUM(O9:O12), "") | G9: =IFERROR(SUM(B9:F9), "") | K9: 3 | L9: Plate | M9: 40 | N9: IS2062: E250A | O9: =IFERROR('BOM RIG ADAPTOR'!I6, "") | P9: =IFERROR('BOM RIG ADAPTOR'!O6, "") | Q9: =IFERROR(M9*1500*3000*0.00000785*1/2, "") | R9: =IFERROR(IF(Q9>P9,Q9,IF(Q9<P9,P9)), "") | S9: =IFERROR((R9-O9)/R9, "") | AC9: Paint Applying Cost (Labour and Consuables) | AG9: =IFERROR(AD3*500, "") | AH9: =IFERROR(AD3*500, "") | AI9: `@500 SQM
A10: SCRAP (KG) | D10: =IFERROR((D8-D9)*85%, "") | E10: =IFERROR((E8-E9)*85%, "") | F10: =IFERROR((F8-F9)*85%, "") | G10: =IFERROR((G8-G9)/G8, "") | K10: 4 | L10: Plate | M10: 32 | N10: IS2062: E250A | O10: =IFERROR('BOM RIG ADAPTOR'!I7, "") | P10: =IFERROR('BOM RIG ADAPTOR'!O7, "") | Q10: =IFERROR(M10*1500*3000*0.00000785*1/2, "") | R10: =IFERROR(IF(Q10>P10,Q10,IF(Q10<P10,P10)), "") | S10: =IFERROR((R10-O10)/R10, "") | X10: Total Paint Cost | AG10: =IFERROR(AG8+AG9, "") | AH10: =IFERROR(AH8+AH9, "")
A11: RM RATE (RS/KG) | D11: 120 | E11: 95 | F11: 75 | G11: =IFERROR(SUMPRODUCT(B11:F11,B8:F8), "") | K11: 5 | L11: Plate | M11: 25 | N11: IS2062: E250A | O11: =IFERROR('BOM RIG ADAPTOR'!I8, "") | P11: =IFERROR('BOM RIG ADAPTOR'!O8, "") | Q11: =IFERROR(M11*1500*3000*0.00000785*1/2, "") | R11: =IFERROR(IF(Q11>P11,Q11,IF(Q11<P11,P11)), "") | S11: =IFERROR((R11-O11)/R11, "") | X11: Trail & Extra paint touch up cost (25%) | AF11: 0.25 | AG11: =IFERROR(AG10*AF11, "") | AH11: =IFERROR(AH10*AF11, "")
A12: SCRAP RATE (RS/KG) | D12: 33 | E12: 33 | F12: 33 | K12: 6 | L12: Plate | M12: 20 | N12: IS2062: E250A | O12: =IFERROR('BOM RIG ADAPTOR'!I9+'BOM RIG ADAPTOR'!I10, "") | P12: =IFERROR('BOM RIG ADAPTOR'!O9+'BOM RIG ADAPTOR'!O10, "") | Q12: =IFERROR(M12*1500*3000*0.00000785*1/4, "") | R12: =IFERROR(IF(Q12>P12,Q12,IF(Q12<P12,P12)), "") | S12: =IFERROR((R12-O12)/R12, "") | X12: Total cost | AG12: =IFERROR(AG11+AG10, "") | AH12: =IFERROR(AH11+AH10, "") | AI12: =IFERROR(AH12/AD3, "")
A13: NET RM COST (RS) | B13: =IFERROR((B8*B11)-(B10*B12), "") | C13: =IFERROR((C8*C11)-(C10*C12), "") | D13: =IFERROR((D8*D11)-(D10*D12), "") | E13: =IFERROR((E8*E11)-(E10*E12), "") | F13: =IFERROR((F8*F11)-(F10*F12), "") | G13: =IFERROR(SUM(B13:F13), "") | AG13: =IFERROR(AG12/AD3, "") | AH13: =IFERROR(AH12/AD3, "")
A14: TOTAL (RS) | B14: =IFERROR(SUM(B13:F13), "") | G14: =IFERROR(G13/G9, "")
A15: BOP COST
A16: BOP COST (RS) | F16: 0
A17: Fastener Cost | F17: 0
A18: Pins and Shaft | F18: 0
A19: TOTAL BOP | F19: =IFERROR(SUM(F16:F18), "")
A20: TOTAL OF RM + BOP (RS) | F20: =IFERROR(B14+F19, "")
A21: PROCESS COST
A22: SPEC | B22: QTY | E22: RATE | F22: TOTAL COST
A23: LASER /PLASMA/PIPE - Cutting (Min.) | B23: =IFERROR(63.5*F3, "") | E23: 75 | F23: =IFERROR(B23*E23, "") | H23: =IFERROR(F23/$G$9, "")
A24: Machining (Hrs) | B24: =IFERROR('BOM RIG ADAPTOR'!V3/60, "") | E24: 3200 | F24: =IFERROR(B24*E24, "") | H24: =IFERROR(F24/$G$9, "")
A25: BENDING BY CNC BENDING (STROKE) | B25: =IFERROR('BOM RIG ADAPTOR'!T3, "") | E25: 200 | F25: =IFERROR(B25*E25, "") | H25: =IFERROR(F25/$G$9, "")
A26: MIG WELDING (MTR.) | B26: =IFERROR(45*F3, "") | E26: 250 | F26: =IFERROR(B26*E26, "") | H26: =IFERROR(F26/$G$9, "")
A27: GRINDING/BUFFING & FINISHING (hrs) | B27: =IFERROR(B26*0.2, "") | E27: 250 | F27: =IFERROR(B27*E27, "") | H27: =IFERROR(F27/$G$9, "")
A28: INSPECTION & TESTING (HRS) | B28: =IFERROR(G9*2.5%, "") | E28: 750 | F28: =IFERROR(B28*E28, "") | H28: =IFERROR(F28/$G$9, "")
A29: STRESS RELIEVING | B29: =IFERROR(G9, "") | E29: 7.5 | F29: =IFERROR(B29*E29, "") | H29: =IFERROR(F29/$G$9, "")
A30: Shot Blasting | B30: =IFERROR(G9, "") | E30: 5 | F30: =IFERROR(E30*B30, "") | H30: =IFERROR(F30/$G$9, "")
A31: Painting | B31: =IFERROR(12.5*F3, "") | E31: 1208.2 | F31: =IFERROR(B31*E31, "") | H31: =IFERROR(F31/$G$9, "")
A32: Assembly, Fitting, Punching, Misce. | B32: =IFERROR(G9/70, "") | E32: 500 | F32: =IFERROR(E32*B32, "") | H32: =IFERROR(F32/$G$9, "")
A33: TOTAL COST OF PC | F33: =IFERROR(SUM(F23:F32), "") | H33: =IFERROR(F33/$G$9, "")
A34: TOTAL RM+BOP+PC | F34: =IFERROR(F20+F33, "") | H34: =IFERROR(F34/$G$9, "")
A35: OH + Contingency | E35: 0.05 | F35: =IFERROR(E35*F34, "") | H35: =IFERROR(F35/$G$9, "")
A36: Total Product Cost Without Profit | F36: =IFERROR(SUM(F34:F35), "") | H36: =IFERROR(F36/$G$9, "")
A37: Total Cost Per Part | F37: =IFERROR(F36/F3, "") | H37: =IFERROR(F37/$G$9, "") | I37: =IFERROR(F37/G8, "")
A40: NON-RECURRING COST
A41: ENGINEERING CHARGES | E41: 1 | F41: 50000
A42: DEVELOPMENT OF JIG AND FIXTURES (01 time) | E42: 1 | F42: =IFERROR(F51*E42, "")
...

Sheet BOM RIG ADAPTOR
A1: S.No | B1: Level | O1: 0.08 | Q1: 0.1 | S1: 25 | W1: 550 | Z1: 0.25 | AC1: 1
B2: Level | C2: Drawing No. | D2: Rev | E2: Description | F2: Qty. | G2: Total Qty. | H2: Net Weight (Kg) | I2: Total Wt. (Kg) | J2: Type | K2: Material Grade | L2: IS Size (mm) | M2: Width | N2: Length | O2: Gross Wt (kg) | P2: Total Gross Wt.(kg) | Q2: Cutting Perimeter | R2: Cutting Time | S2: Cutting Cost | T2: No. of bends | U2: Bending Details | V2: Machining Time (min) | W2: Machining Cost | X2: Other Process | Y2: Other process Cost | Z2: Welding Length (M) | AA2: Remarks | AB2: Paint | AC2: Surface Area SQM
A3: 1 | B3: 0 | C3: 2118 626 01A1 | E3: STEERING ROLL HANDLING RIG ADAPTOR ASSEMBLY | F3: 5 | G3: =IFERROR(F3, "") | H3: 659.39 | I3: =IFERROR(H3*F3, "") | J3: Final Assy | R3: =IFERROR(SUM(R4:R10), "") | T3: =IFERROR(SUMPRODUCT($F$4:$F$10,T4:T10), "") | V3: =IFERROR(SUMPRODUCT($G$4:$G$10,V4:V10)+(12*60*G3), "") | W3: =IFERROR(SUM(W4:W10)+(12*60*4500/60*G3), "") | Z3: =IFERROR(SUM(Z4:Z10)*(1+$Z$1)/1000, "") | AC3: =IFERROR(SUM(AC4:AC10)*(1+$Z$1), "")
A4: 2 | B4: 1 | E4: PIPE DN350 x SCH-80. x 685 LG. ENDS SQ. | F4: 1 | G4: =IFERROR(F4*$G$3, "") | H4: 104.73 | I4: =IFERROR(H4*G4, "") | J4: Pipe | K4: ASTM A106 GR.B | L4: OD 355.6 x 19.05 thk | N4: 685 | O4: =IFERROR(158.11*N4/1000*(1+O1)*G4, "") | P4: =IFERROR(158.11*6, "") | V4: 60 | W4: =IFERROR(V4*500/60*F4, "") | AA4: Facing On lathe and Size
A5: 3 | B5: 2 | E5: PLATE 320 O.D. x 190 I.D. x 180 LG. ENDS SQ. | F5: 1 | G5: =IFERROR(F5*$G$3, "") | H5: 62.21 | I5: =IFERROR(H5*G5, "") | J5: Block | K5: IS2062: E250A | L5: 180 | M5: 190 | N5: 320 | O5: =IFERROR(L5*M5*N5*0.00000785*(1+$O$1)*G5, "") | P5: =IFERROR(O5*(1+20%), "") | V5: =IFERROR(60*4, "") | W5: =IFERROR(V5*500/60*F5, "") | AA5: Cone shape
A6: 4 | B6: 3 | E6: PLATE 40 THK. x 490 x 985 LG. | F6: 1 | G6: =IFERROR(F6*$G$3, "") | H6: 119.85 | I6: =IFERROR(H6*G6, "") | J6: Plate | K6: IS2062: E250A | L6: 40 | M6: 490 | N6: 985 | O6: =IFERROR(L6*M6*N6*0.00000785*(1+$O$1)*G6, "") | P6: =IFERROR(O6, "")
A7: 5 | B7: 4 | E7: PLATE 28 THK. x 610 x 1150 LG. | F7: 1 | G7: =IFERROR(F7*$G$3, "") | H7: 113.77 | I7: =IFERROR(H7*G7, "") | J7: Plate | K7: IS2062: E250A | L7: 32 | M7: 610 | N7: 1150 | O7: =IFERROR(L7*M7*N7*0.00000785*(1+$O$1)*G7, "") | P7: =IFERROR(O7, "")
A8: 6 | B8: 5 | E8: PLATE 25 THK. x 585 x 1130 LG. | F8: 2 | G8: =IFERROR(F8*$G$3, "") | H8: 121.63 | I8: =IFERROR(H8*G8, "") | J8: Plate | K8: IS2062: E250A | L8: 25 | M8: 585 | N8: 1130 | O8: =IFERROR(L8*M8*N8*0.00000785*(1+$O$1)*G8, "") | P8: =IFERROR(O8, "") | V8: 15 | W8: =IFERROR(V8*500/60*F8, "")
A9: 7 | B9: 6 | E9: PLATE 20 THK. x 220 x 220 LG. | F9: 1 | G9: =IFERROR(F9*$G$3, "") | H9: 4.76 | I9: =IFERROR(H9*G9, "") | J9: Plate | K9: IS2062: E250A | L9: 20 | M9: 220 | N9: 220 | O9: =IFERROR(L9*M9*N9*0.00000785*(1+$O$1)*G9, "") | P9: =IFERROR(O9, "")
A10: 8 | B10: 7 | E10: PLATE 20 THK. x 100 x 175 LG. | F10: 3 | G10: =IFERROR(F10*$G$3, "") | H10: 2.6 | I10: =IFERROR(H10*G10, "") | J10: Plate | K10: IS2062: E250A | L10: 20 | M10: 100 | N10: 175 | O10: =IFERROR(L10*M10*N10*0.00000785*(1+$O$1)*G10, "") | P10: =IFERROR(O10, "")
