Workbook
Name a: '[1]BOM '!#REF!
Name a: '[1]BOM '!#REF!
Name a: '[1]BOM '!#REF!
Name a: '[1]BOM '!#REF!
Name a: '[1]BOM '!#REF!
Name a: '[1]BOM '!#REF!
Name a: '[1]BOM '!#REF!
Name a: '[1]BOM '!#REF!
Name a: '[1]BOM '!#REF!
Name a: '[1]BOM '!#REF!
Name a: '[1]BOM '!#REF!
Name a: '[1]BOM '!#REF!
Name a: '[1]BOM '!#REF!
Name a: '[1]BOM '!#REF!
Name a: #REF!
Name a: #REF!
Name a_1: #REF!
Name a_1: #REF!
Name a_1: #REF!
Name a_1: #REF!
Name a_1: #REF!
Name a_1: #REF!
Name a_1: #REF!
Name a_1: #REF!
Name a_1: #REF!
Name a_1: #REF!
Name a_1: #REF!
Name a_1: #REF!
Name a_1: #REF!
Name a_1: #REF!
Name a_1: #REF!
Name a_1: #REF!
Name b: #REF!
Name b: #REF!
Name b: #REF!
Name b: #REF!
Name b: #REF!
Name b: #REF!
Name b: #REF!
Name b: #REF!
Name b: #REF!
Name b: #REF!
Name b: #REF!
Name b: #REF!
Name b: #REF!
Name b: #REF!
Name b: #REF!
Name b: #REF!

Sheet Customer Data 
A1: S.NO | B1: PartID | C1: Description | D1: Usage
A2: 1 | B2: AY30013 | C2: WELDMENT, PC4100 R2D SLAVE SKID, PC4100 | D2: 1
A3: 2 | B3: AY30017 | C3: WELDMENT, FALSE FLOOR, PC4100 | D3: 2
A4: 3 | B4: AY30018 | C4: WELDMENT, HINGED FLOOR, PC4100 | D4: 1
A5: 4 | B5: AY30027 | C5: WELDMENT, HINGED FLOOR, PC4100 | D5: 23
A6: 5 | B6: AY30062 | C6: WELDMENT, SAFETY BAR, PC4100 | D6: 1
A7: 6 | B7: AY30084 | C7: HAND RAIL, WELDMENT, 42" CATWALK, PC4100 | D7: 4
A8: 7 | B8: AY30107 | C8: WELDMENT,SKATE BODY, REVERSE VEE,PC4100 | D8: 1
A9: 8 | B9: AY30133 | C9: WELDMENT, RAMP RAIL, PC4100 | D9: 1
A10: 9 | B10: AY30134 | C10: WLDMNT, RAMP, SHEAVE SUB B, PC4100 | D10: 1
A11: 10 | B11: AY30144 | C11: WELDMENT, 30FT LIFT ARM, PC4100 | D11: 1
A12: 11 | B12: AY30150 | C12: WELDMENT, SPEAR FRAME, PC4100 | D12: 1
A13: 12 | B13: AY30160 | C13: WELDMENT, 42D CARRIER REAR, PC4100 | D13: 1
... A16: 15 | B16: AY50135 | C16: KIT, LABELS, SAFETY, ENG/ARA, PC4000 | D16: 1

Sheet Quote Package PC4100
D1: ITEM-1 | F1: ITEM-2 | H1: ITEM-3 | J1: ITEM-4 | L1: ITEM-5 | N1: ITEM-6 | P1: ITEM-7 | R1: ITEM-8 | T1: ITEM-9 | V1: ITEM-10 | X1: ITEM-11 | Z1: ITEM-12 | AB1: ITEM-13 | AD1: ITEM-14
A2: RECURRING COST | D2: Assy. No | E2: Qty. | F2: Assy. No | G2: Qty. | H2: Assy. No | I2: Qty. | J2: Assy. No | K2: Qty. | L2: Assy. No | M2: Qty. | N2: Assy. No | O2: Qty. | P2: Assy. No | Q2: Qty. | R2: Assy. No | S2: Qty. | T2: Assy. No | U2: Qty. | V2: Assy. No | W2: Qty. | X2: Assy. No | Y2: Qty. | Z2: Assy. No | AA2: Qty. | AB2: Assy. No | AC2: Qty. | AD2: Assy. No | AE2: Qty.
D3: ='BOM R2D CatWalk'!G4 -> AY30013 | E3: ='BOM R2D CatWalk'!K4 -> 1 | F3: ='BOM R2D CatWalk'!G93 -> AY30017 | G3: ='BOM R2D CatWalk'!K93 -> 2 | H3: ='BOM R2D CatWalk'!G97 -> AY30018 | I3: ='BOM R2D CatWalk'!K97 -> 1 | J3: ='BOM R2D CatWalk'!G100 -> AY30027 | K3: ='BOM R2D CatWalk'!K100 -> 23 | L3: ='BOM R2D CatWalk'!G105 -> AY30062 | M3: ='BOM R2D CatWalk'!K105 -> 1 | N3: ='BOM R2D CatWalk'!G109 -> AY30084 | O3: ='BOM R2D CatWalk'!K109 -> 4 | P3: ='BOM R2D CatWalk'!G114 -> AY30107 | Q3: ='BOM R2D CatWalk'!K114 -> 1 | R3: ='BOM R2D CatWalk'!G119 -> AY30133 | S3: ='BOM R2D CatWalk'!K119 -> 1 | T3: ='BOM R2D CatWalk'!G128 -> AY30134 | U3: ='BOM R2D CatWalk'!K128 -> 1 | V3: ='BOM R2D CatWalk'!G145 -> AY30144 | W3: ='BOM R2D CatWalk'!K145 -> 1 | X3: ='BOM R2D CatWalk'!G162 -> AY30150 | Y3: ='BOM R2D CatWalk'!K162 -> 1 | Z3: ='BOM R2D CatWalk'!G171 -> AY30160 | AA3: ='BOM R2D CatWalk'!K171 -> 1 | AB3: ='BOM R2D CatWalk'!G187 -> AY51606 | AC3: ='BOM R2D CatWalk'!K187 -> 1 | AD3: ='BOM R2D CatWalk'!G201 -> AY30130 | AE3: ='BOM R2D CatWalk'!K201 -> 1
A4: A. | B4: RM Cost | D4: Weight in Kg. | E4: Price in INR | F4: Weight in Kg. | G4: Price in INR | H4: Weight in Kg. | I4: Price in INR | J4: Weight in Kg. | K4: Price in INR | L4: Weight in Kg. | M4: Price in INR | N4: Weight in Kg. | O4: Price in INR | P4: Weight in Kg. | Q4: Price in INR | R4: Weight in Kg. | S4: Price in INR | T4: Weight in Kg. | U4: Price in INR | V4: Weight in Kg. | W4: Price in INR | X4: Weight in Kg. | Y4: Price in INR | Z4: Weight in Kg. | AA4: Price in INR | AB4: Weight in Kg. | AC4: Price in INR | AD4: Weight in Kg. | AE4: Price in INR
A5: i. | B5: RM Gross Weight | D5: ='Item-1_AY30013'!H8 -> 5297.8014 | F5: ='Item-2_AY30017'!F8 -> 159.73139 | H5: ='Item-3_AY30018'!F8 -> 29.666872 | J5: ='Item-4_AY30027'!F8 -> 490.53806 | L5: ='Item-5_AY30062'!F8 -> 61.97492 | N5: ='Item-6_AY30084'!F8 -> 97.8406 | P5: ='Item-7_AT30107'!F8 -> 137.44273 | R5: ='Item-8_AT30133'!F8 -> 137.03074 | T5: ='Item-9_AT30134'!F8 -> 900.30678 | V5: ='Item-10_AT30144'!G8 -> 1231.9456 | X5: ='Item-11_AT30150'!G8 -> 100.98498 | Z5: ='Item-12_AY30160'!G8 -> 1032.2847 | AB5: ='Item-13_AY51606'!G8 -> 250.32865 | AD5: ='Item-14_AY30130'!G8 -> 4814.2978
A6: ii. | B6: RM Net Weight | D6: ='Item-1_AY30013'!H9 -> 4052.0664 | F6: ='Item-2_AY30017'!F9 -> 130.332 | H6: ='Item-3_AY30018'!F9 -> 26.8 | J6: ='Item-4_AY30027'!F9 -> 443.05813 | L6: ='Item-5_AY30062'!F9 -> 20.6876 | N6: ='Item-6_AY30084'!F9 -> 88.946 | P6: ='Item-7_AT30107'!F9 -> 80.5 | R6: ='Item-8_AT30133'!F9 -> 124.5734 | T6: ='Item-9_AT30134'!F9 -> 370.42611 | V6: ='Item-10_AT30144'!G9 -> 1044.4723 | X6: ='Item-11_AT30150'!G9 -> 65.53 | Z6: ='Item-12_AY30160'!G9 -> 579.6 | AB6: ='Item-13_AY51606'!G9 -> 177.87298 | AD6: ='Item-14_AY30130'!G9 -> 4086.1094
A7: iii. | B7: Raw Material Cost | E7: ='Item-1_AY30013'!H13 -> 545874.98 | G7: ='Item-2_AY30017'!F13 -> 16346.24 | I7: ='Item-3_AY30018'!F13 -> 2601.2135 | K7: ='Item-4_AY30027'!F13 -> 43008.907 | M7: ='Item-5_AY30062'!F13 -> 5758.6471 | O7: ='Item-6_AY30084'!F13 -> 19354.65 | Q7: ='Item-7_AT30107'!F13 -> 11003.22 | S7: ='Item-8_AT30133'!F13 -> 27107.172 | U7: ='Item-9_AT30134'!F13 -> 74070.474 | W7: ='Item-10_AT30144'!G13 -> 228672.72 | Y7: ='Item-11_AT30150'!G13 -> 16765.529 | AA7: ='Item-12_AY30160'!G13 -> 156415.22 | AC7: ='Item-13_AY51606'!G13 -> 20790.642 | AE7: ='Item-14_AY30130'!G13 -> 580640.73
A8: iv. | B8: Shaft Cost /Fastener/ BOP | E8: ='Item-1_AY30013'!G17 -> 8000 | G8: 0 | I8: 0 | K8: 0 | M8: 0 | O8: 0 | Q8: 0 | S8: 0 | U8: 0 | W8: 0 | Y8: 0 | AA8: 0 | AC8: 0 | AE8: 0
B9: TOTAL RM COST | E9: =SUM(E7:E8) -> 553874.98 | G9: =SUM(G7:G8) -> 16346.24 | I9: =SUM(I7:I8) -> 2601.2135 | K9: =SUM(K7:K8) -> 43008.907 | M9: =SUM(M7:M8) -> 5758.6471 | O9: =SUM(O7:O8) -> 19354.65 | Q9: =SUM(Q7:Q8) -> 11003.22 | S9: =SUM(S7:S8) -> 27107.172 | U9: =SUM(U7:U8) -> 74070.474 | W9: =SUM(W7:W8) -> 228672.72 | Y9: =SUM(Y7:Y8) -> 16765.529 | AA9: =SUM(AA7:AA8) -> 156415.22 | AC9: =SUM(AC7:AC8) -> 20790.642 | AE9: =SUM(AE7:AE8) -> 580640.73
D10: =(D5-D6)/D6 -> 0.30743205 | F10: =(F5-F6)/F6 -> 0.22557306 | H10: =(H5-H6)/H6 -> 0.10697282 | J10: =(J5-J6)/J6 -> 0.10716412 | L10: =(L5-L6)/L6 -> 1.995752 | N10: =(N5-N6)/N6 -> 0.1 | P10: =(P5-P6)/P6 -> 0.70736315 | R10: =(R5-R6)/R6 -> 0.1 | T10: =(T5-T6)/T6 -> 1.4304626 | V10: =(V5-V6)/V6 -> 0.17949093 | X10: =(X5-X6)/X6 -> 0.54104963 | Z10: =(Z5-Z6)/Z6 -> 0.78102942 | AB10: =(AB5-AB6)/AB6 -> 0.40734503 | AD10: =(AD5-AD6)/AD6 -> 0.17821071
A11: B. | B11: Process Cost
A12: i. | B12: Assy Cost | C12: 0 | E12: 0 | G12: 0 | I12: 0 | K12: 0 | M12: 0 | O12: 0 | Q12: 0 | S12: 0 | U12: 0 | W12: 0 | Y12: 0 | AA12: 0 | AC12: 0 | AE12: 0
A13: ii. | B13: Fabrication / Process Cost | C13: 0 | E13: ='Item-1_AY30013'!G33 -> 336234.83 | G13: ='Item-2_AY30017'!E33 -> 10766.814 | I13: ='Item-3_AY30018'!E33 -> 2807.9474 | K13: ='Item-4_AY30027'!E33 -> 55898.463 | M13: ='Item-5_AY30062'!E33 -> 1667.0183 | O13: ='Item-6_AY30084'!E33 -> 8215.6491 | Q13: ='Item-7_AT30107'!E33 -> 9116.1528 | S13: ='Item-8_AT30133'!E33 -> 12697.733 | U13: ='Item-9_AT30134'!E33 -> 42971.149 | W13: ='Item-10_AT30144'!F33 -> 93760.099 | Y13: ='Item-11_AT30150'!F33 -> 7281.4489 | AA13: ='Item-12_AY30160'!F33 -> 50850.186 | AC13: ='Item-13_AY51606'!F33 -> 13325.958 | AE13: ='Item-14_AY30130'!F33 -> 443934.3
A14: iii. | B14: Paint | C14: 20 | E14: =D6*$C$14 -> 81041.327 | G14: =F6*$C$14 -> 2606.64 | I14: =H6*$C$14 -> 536 | K14: =J6*$C$14 -> 8861.1626 | M14: =L6*$C$14 -> 413.752 | O14: =N6*$C$14 -> 1778.92 | Q14: =P6*$C$14 -> 1610 | S14: =R6*$C$14 -> 2491.468 | U14: =T6*$C$14 -> 7408.5221 | W14: =V6*$C$14 -> 20889.446 | Y14: =X6*$C$14 -> 1310.6 | AA14: =Z6*$C$14 -> 11592 | AC14: =AB6*$C$14 -> 3557.4595 | AE14: =AD6*$C$14 -> 81722.187
A15: iv. | B15: Inspection and Testing | C15: 12 | E15: =D6*$C$15 -> 48624.796 | G15: =F6*$C$15 -> 1563.984 | I15: =H6*$C$15 -> 321.6 | K15: =J6*$C$15 -> 5316.6976 | M15: =L6*$C$15 -> 248.2512 | O15: =N6*$C$15 -> 1067.352 | Q15: =P6*$C$15 -> 966 | S15: =R6*$C$15 -> 1494.8808 | U15: =T6*$C$15 -> 4445.1133 | W15: =V6*$C$15 -> 12533.668 | Y15: =X6*$C$15 -> 786.36 | AA15: =Z6*$C$15 -> 6955.2 | AC15: =AB6*$C$15 -> 2134.4757 | AE15: =AD6*$C$15 -> 49033.312
A16: v. | B16: Packaging | C16: Canrig Scope | E16: 0 | G16: 0 | I16: 0 | K16: 0 | M16: 0 | O16: 0 | Q16: 0 | S16: 0 | U16: 0 | W16: 0 | Y16: 0 | AA16: 0 | AC16: 0 | AE16: 0
B17: TOTAL BASIC COST | E17: =SUM(E9:E16) -> 1019775.9 | G17: =SUM(G9:G16) -> 31283.677 | I17: =SUM(I9:I16) -> 6266.761 | K17: =SUM(K9:K16) -> 113085.23 | M17: =SUM(M9:M16) -> 8087.6686 | O17: =SUM(O9:O16) -> 30416.571 | Q17: =SUM(Q9:Q16) -> 22695.373 | S17: =SUM(S9:S16) -> 43791.254 | U17: =SUM(U9:U16) -> 128895.26 | W17: =SUM(W9:W16) -> 355855.93 | Y17: =SUM(Y9:Y16) -> 26143.938 | AA17: =SUM(AA9:AA16) -> 225812.6 | AC17: =SUM(AC9:AC16) -> 39808.535 | AE17: =SUM(AE9:AE16) -> 1155330.5
A19: C. | B19: Fixed Cost
A20: i | B20: ICC Cost | C20: 0.015 | E20: =E22*$C$20 -> 15769.731 | G20: =G22*$C$20 -> 483.76821 | I20: =I22*$C$20 -> 96.908675 | K20: =K22*$C$20 -> 1748.7407 | M20: =M22*$C$20 -> 125.06704 | O20: =O22*$C$20 -> 470.35934 | Q20: =Q22*$C$20 -> 350.95938 | S20: =S22*$C$20 -> 677.18434 | U20: =U22*$C$20 -> 1993.2256 | W20: =W22*$C$20 -> 5502.9268 | Y20: =Y22*$C$20 -> 404.2877 | AA20: =AA22*$C$20 -> 3491.9475 | AC20: =AC22*$C$20 -> 615.59591 | AE20: =AE22*$C$20 -> 17865.936
A21: ii | B21: Rejection | C21: 0.015 | E21: =E22*$C$21 -> 15769.731 | G21: =G22*$C$21 -> 483.76821 | I21: =I22*$C$21 -> 96.908675 | K21: =K22*$C$21 -> 1748.7407 | M21: =M22*$C$21 -> 125.06704 | O21: =O22*$C$21 -> 470.35934 | Q21: =Q22*$C$21 -> 350.95938 | S21: =S22*$C$21 -> 677.18434 | U21: =U22*$C$21 -> 1993.2256 | W21: =W22*$C$21 -> 5502.9268 | Y21: =Y22*$C$21 -> 404.2877 | AA21: =AA22*$C$21 -> 3491.9475 | AC21: =AC22*$C$21 -> 615.59591 | AE21: =AE22*$C$21 -> 17865.936
B22: Sub Total | E22: =SUM(E20:E21)+E17 -> 1051315.4 | G22: =SUM(G20:G21)+G17 -> 32251.214 | I22: =SUM(I20:I21)+I17 -> 6460.5783 | K22: =SUM(K20:K21)+K17 -> 116582.71 | M22: =SUM(M20:M21)+M17 -> 8337.8027 | O22: =SUM(O20:O21)+O17 -> 31357.289 | Q22: =SUM(Q20:Q21)+Q17 -> 23397.292 | S22: =SUM(S20:S21)+S17 -> 45145.622 | U22: =SUM(U20:U21)+U17 -> 132881.71 | W22: =SUM(W20:W21)+W17 -> 366861.79 | Y22: =SUM(Y20:Y21)+Y17 -> 26952.513 | AA22: =SUM(AA20:AA21)+AA17 -> 232796.5 | AC22: =SUM(AC20:AC21)+AC17 -> 41039.727 | AE22: =SUM(AE20:AE21)+AE17 -> 1191062.4
A24: D. | B24: Variable Cost
A25: i. | B25: Contingency / Warranty | C25: 0.01 | E25: =E28*$C$25 -> 14017.539 | G25: =G28*$C$25 -> 430.01618 | I25: =I28*$C$25 -> 86.141044 | K25: =K28*$C$25 -> 1554.4362 | M25: =M28*$C$25 -> 111.1707 | O25: =O28*$C$25 -> 418.09719 | Q25: =Q28*$C$25 -> 311.96389 | S25: =S28*$C$25 -> 601.94163 | U25: =U28*$C$25 -> 1771.7561 | W25: =W28*$C$25 -> 4891.4905 | Y25: =Y28*$C$25 -> 359.36684 | AA25: =AA28*$C$25 -> 3103.9533 | AC25: =AC28*$C$25 -> 547.19636 | AE25: =AE28*$C$25 -> 15880.832
A26: ii. | B26: Overheads | C26: 0.12 | E26: =E28*$C$26 -> 168210.46 | G26: =G28*$C$26 -> 5160.1942 | I26: =I28*$C$26 -> 1033.6925 | K26: =K28*$C$26 -> 18653.234 | M26: =M28*$C$26 -> 1334.0484 | O26: =O28*$C$26 -> 5017.1663 | Q26: =Q28*$C$26 -> 3743.5667 | S26: =S28*$C$26 -> 7223.2996 | U26: =U28*$C$26 -> 21261.074 | W26: =W28*$C$26 -> 58697.886 | Y26: =Y28*$C$26 -> 4312.4021 | AA26: =AA28*$C$26 -> 37247.44 | AC26: =AC28*$C$26 -> 6566.3563 | AE26: =AE28*$C$26 -> 190569.98
A27: iii. | B27: Contribution / Profit | C27: 0.12 | E27: =E28*$C$27 -> 168210.46 | G27: =G28*$C$27 -> 5160.1942 | I27: =I28*$C$27 -> 1033.6925 | K27: =K28*$C$27 -> 18653.234 | M27: =M28*$C$27 -> 1334.0484 | O27: =O28*$C$27 -> 5017.1663 | Q27: =Q28*$C$27 -> 3743.5667 | S27: =S28*$C$27 -> 7223.2996 | U27: =U28*$C$27 -> 21261.074 | W27: =W28*$C$27 -> 58697.886 | Y27: =Y28*$C$27 -> 4312.4021 | AA27: =AA28*$C$27 -> 37247.44 | AC27: =AC28*$C$27 -> 6566.3563 | AE27: =AE28*$C$27 -> 190569.98
B28: Total Price | E28: =SUM(E22:E27) -> 1401753.9 | G28: =SUM(G22:G27) -> 43001.618 | I28: =SUM(I22:I27) -> 8614.1044 | K28: =SUM(K22:K27) -> 155443.62 | M28: =SUM(M22:M27) -> 11117.07 | O28: =SUM(O22:O27) -> 41809.719 | Q28: =SUM(Q22:Q27) -> 31196.389 | S28: =SUM(S22:S27) -> 60194.163 | U28: =SUM(U22:U27) -> 177175.61 | W28: =SUM(W22:W27) -> 489149.05 | Y28: =SUM(Y22:Y27) -> 35936.684 | AA28: =SUM(AA22:AA27) -> 310395.33 | AC28: =SUM(AC22:AC27) -> 54719.636 | AE28: =SUM(AE22:AE27) -> 1588083.2
A30: F | B30: Transportation | C30: EX Works | E30: 0 | G30: 0 | I30: 0 | K30: 0 | M30: 0 | O30: 0 | Q30: 0 | S30: 0 | U30: 0 | W30: 0 | Y30: 0 | AA30: 0 | AC30: 0 | AE30: 0
B31: Total Price for X Parts | D31: =E3 -> 1 | E31: =SUM(E28:E30) -> 1401753.9 | F31: =G3 -> 2 | G31: =SUM(G28:G30) -> 43001.618 | H31: =I3 -> 1 | I31: =SUM(I28:I30) -> 8614.1044 | J31: =K3 -> 23 | K31: =SUM(K28:K30) -> 155443.62 | L31: =M3 -> 1 | M31: =SUM(M28:M30) -> 11117.07 | N31: =O3 -> 4 | O31: =SUM(O28:O30) -> 41809.719 | P31: =Q3 -> 1 | Q31: =SUM(Q28:Q30) -> 31196.389 | R31: =S3 -> 1 | S31: =SUM(S28:S30) -> 60194.163 | T31: =U3 -> 1 | U31: =SUM(U28:U30) -> 177175.61 | V31: =W3 -> 1 | W31: =SUM(W28:W30) -> 489149.05 | X31: =Y3 -> 1 | Y31: =SUM(Y28:Y30) -> 35936.684 | Z31: =AA3 -> 1 | AA31: =SUM(AA28:AA30) -> 310395.33 | AB31: =AC3 -> 1 | AC31: =SUM(AC28:AC30) -> 54719.636 | AD31: =AE3 -> 1 | AE31: =SUM(AE28:AE30) -> 1588083.2 | AF31: =SUM(E31:AE31) -> 4408629.1
B32: Total Cost Each Part | E32: =E31/E3 -> 1401753.9 | G32: =G31/G3 -> 21500.809 | I32: =I31/I3 -> 8614.1044 | K32: =K31/K3 -> 6758.4181 | M32: =M31/M3 -> 11117.07 | O32: =O31/O3 -> 10452.43 | Q32: =Q31/Q3 -> 31196.389 | S32: =S31/S3 -> 60194.163 | U32: =U31/U3 -> 177175.61 | W32: =W31/W3 -> 489149.05 | Y32: =Y31/Y3 -> 35936.684 | AA32: =AA31/AA3 -> 310395.33 | AC32: =AC31/AC3 -> 54719.636 | AE32: =AE31/AE3 -> 1588083.2
B34: Rate Per Gross Wt kg | E34: =E31/D5 -> 264.59162 | G34: =G31/F5 -> 269.21207 | I34: =I31/H5 -> 290.36107 | K34: =K31/J5 -> 316.8839 | M34: =M31/L5 -> 179.38015 | O34: =O31/N5 -> 427.32484 | Q34: =Q31/P5 -> 226.97736 | S34: =S31/R5 -> 439.27489 | U34: =U31/T5 -> 196.79471 | W34: =W31/V5 -> 397.05409 | Y34: =Y31/X5 -> 355.86167 | AA34: =AA31/Z5 -> 300.68773 | AC34: =AC31/AB5 -> 218.59118 | AE34: =AE31/AD5 -> 329.86809
B35: Rate Per Net Wt kg | E35: =E31/D6 -> 345.93556 | G35: =G31/F6 -> 329.93907 | I35: =I31/H6 -> 321.42181 | K35: =K31/J6 -> 350.84249 | M35: =M31/L6 -> 537.37844 | O35: =O31/N6 -> 470.05733 | Q35: =Q31/P6 -> 387.53279 | S35: =S31/R6 -> 483.20238 | U35: =U31/T6 -> 478.30218 | W35: =W31/V6 -> 468.3217 | Y35: =Y31/X6 -> 548.40049 | AA35: =AA31/Z6 -> 535.5337 | AC35: =AC31/AB6 -> 307.63322 | AE35: =AE31/AD6 -> 388.65411
B36: Internal Cal. Cost Per X parts | D36: =E3 -> 1 | E36: ='Item-1_AY30013'!G36 -> 979120.8 | F36: =G3 -> 2 | G36: ='Item-2_AY30017'!E36 -> 29824.359 | H36: =I3 -> 1 | I36: ='Item-3_AY30018'!E36 -> 5950.0771 | J36: =K3 -> 23 | K36: ='Item-4_AY30027'!E36 -> 108798.11 | L36: =M3 -> 1 | M36: ='Item-5_AY30062'!E36 -> 8168.2319 | N36: =O3 -> 4 | O36: ='Item-6_AY30084'!E36 -> 30327.329 | P36: =Q3 -> 1 | Q36: ='Item-7_AT30107'!E36 -> 22131.311 | R36: =S3 -> 1 | S36: ='Item-8_AT30133'!E36 -> 43785.395 | T36: =U3 -> 1 | U36: ='Item-9_AT30134'!E36 -> 128745.79 | V36: =W3 -> 1 | W36: ='Item-10_AT30144'!F36 -> 354676.1 | X36: =Y3 -> 1 | Y36: ='Item-11_AT30150'!F36 -> 26451.676 | Z36: =AA3 -> 1 | AA36: ='Item-12_AY30160'!F36 -> 227991.94 | AB36: =AC3 -> 1 | AC36: ='Item-13_AY51606'!F36 -> 37528.26 | AD36: =AE3 -> 1 | AE36: ='Item-14_AY30130'!F36 -> 1127032.5
B37: Margin | E37: =E31-E36 -> 422633.07 | G37: =G31-G36 -> 13177.26 | I37: =I31-I36 -> 2664.0274 | K37: =K31-K36 -> 46645.509 | M37: ='Item-5_AY30062'!E36 -> 8168.2319 | O37: =O31-O36 -> 11482.391 | Q37: =Q31-Q36 -> 9065.0788 | S37: =S31-S36 -> 16408.768 | U37: =U31-U36 -> 48429.828 | W37: =W31-W36 -> 134472.95 | Y37: =Y31-Y36 -> 9485.0087 | AA37: =AA31-AA36 -> 82403.388 | AC37: =AC31-AC36 -> 17191.376 | AE37: =AE31-AE36 -> 461050.67
B38: Margin % | E38: =(E31-E36)/E31 -> 0.30150305 | G38: =(G31-G36)/G31 -> 0.30643637 | I38: =(I31-I36)/I31 -> 0.30926342 | K38: =(K31-K36)/K31 -> 0.30007992 | M38: =(M31-M36)/M31 -> 0.26525319 | O38: =(O31-O36)/O31 -> 0.27463448 | Q38: =(Q31-Q36)/Q31 -> 0.29058102 | S38: =(S31-S36)/S31 -> 0.27259732 | U38: =(U31-U36)/U31 -> 0.27334364 | W38: =(W31-W36)/W31 -> 0.27491201 | Y38: =(Y31-Y36)/Y31 -> 0.26393667 | AA38: =(AA31-AA36)/AA31 -> 0.26547882 | AC38: =(AC31-AC36)/AC31 -> 0.31417197 | AE38: =(AE31-AE36)/AE31 -> 0.29031896
B40: FOR EQS 25% margin | E40: =E32*(100%-75%)/100% -> 350438.47 | G40: =G32*(100%-75%)/100% -> 5375.2023 | I40: =I32*(100%-75%)/100% -> 2153.5261 | K40: =K32*(100%-75%)/100% -> 1689.6045 | M40: =M32*(100%-75%)/100% -> 2779.2676 | O40: =O32*(100%-75%)/100% -> 2613.1074 | Q40: =Q32*(100%-75%)/100% -> 7799.0973 | S40: =S32*(100%-75%)/100% -> 15048.541 | U40: =U32*(100%-75%)/100% -> 44293.903 | W40: =W32*(100%-75%)/100% -> 122287.26 | Y40: =Y32*(100%-75%)/100% -> 8984.171 | AA40: =AA32*(100%-75%)/100% -> 77598.833 | AC40: =AC32*(100%-75%)/100% -> 13679.909 | AE40: =AE32*(100%-75%)/100% -> 397020.8
C41: Per Pcs | E41: =E32-E40 -> 1051315.4 | G41: =G32-G40 -> 16125.607 | I41: =I32-I40 -> 6460.5783 | K41: =K32-K40 -> 5068.8136 | M41: =M32-M40 -> 8337.8027 | O41: =O32-O40 -> 7839.3223 | Q41: =Q32-Q40 -> 23397.292 | S41: =S32-S40 -> 45145.622 | U41: =U32-U40 -> 132881.71 | W41: =W32-W40 -> 366861.79 | Y41: =Y32-Y40 -> 26952.513 | AA41: =AA32-AA40 -> 232796.5 | AC41: =AC32-AC40 -> 41039.727 | AE41: =AE32-AE40 -> 1191062.4 | AF41: =SUM(E41:AE41) -> 3155285.1
A44: NON-RECURRING COST | D44: ITEM-1 | F44: ITEM-2 | H44: ITEM-3 | J44: ITEM-4 | L44: ITEM-5 | N44: ITEM-6 | P44: ITEM-7 | R44: ITEM-8 | T44: ITEM-9 | V44: ITEM-10 | X44: ITEM-11 | Z44: ITEM-12 | AB44: ITEM-13 | AD44: ITEM-14
A45: 1 | B45: ENGINEERING CHARGES | E45: ='Item-1_AY30013'!D51 -> 37500 | G45: ='Item-2_AY30017'!D51 -> 5000 | I45: ='Item-3_AY30018'!D51 -> 0 | K45: ='Item-4_AY30027'!D51 -> 0 | M45: ='Item-5_AY30062'!D51 -> 0 | O45: ='Item-6_AY30084'!D51 -> 0 | Q45: ='Item-7_AT30107'!D51 -> 5000 | S45: ='Item-8_AT30133'!D51 -> 0 | U45: ='Item-9_AT30134'!D51 -> 10000 | W45: ='Item-10_AT30144'!D51 -> 20000 | Y45: ='Item-11_AT30150'!D51 -> 5000 | AA45: ='Item-12_AY30160'!D51 -> 12500 | AC45: ='Item-13_AY51606'!D51 -> 0 | AE45: ='Item-14_AY30130'!D51 -> 17500
A46: 2 | B46: DEVELOPMENT OF JIG AND FIXTURES (01 time) | E46: ='Item-1_AY30013'!D50 -> 421553 | G46: ='Item-2_AY30017'!D50 -> 13585 | I46: ='Item-3_AY30018'!D50 -> 0 | K46: ='Item-4_AY30027'!D50 -> 0 | M46: ='Item-5_AY30062'!D50 -> 0 | O46: ='Item-6_AY30084'!D50 -> 0 | Q46: ='Item-7_AT30107'!D50 -> 14212 | S46: ='Item-8_AT30133'!D50 -> 0 | U46: ='Item-9_AT30134'!D50 -> 56491.875 | W46: ='Item-10_AT30144'!D50 -> 239065.88 | Y46: ='Item-11_AT30150'!D50 -> 7132.875 | AA46: ='Item-12_AY30160'!D50 -> 153574.05 | AC46: ='Item-13_AY51606'!D50 -> 0 | AE46: ='Item-14_AY30130'!D50 -> 542906.87
B47: Sub Total | E47: =SUM(E45:E46) -> 459053 | G47: =SUM(G45:G46) -> 18585 | I47: =SUM(I45:I46) -> 0 | K47: =SUM(K45:K46) -> 0 | M47: =SUM(M45:M46) -> 0 | O47: =SUM(O45:O46) -> 0 | Q47: =SUM(Q45:Q46) -> 19212 | S47: =SUM(S45:S46) -> 0 | U47: =SUM(U45:U46) -> 66491.875 | W47: =SUM(W45:W46) -> 259065.88 | Y47: =SUM(Y45:Y46) -> 12132.875 | AA47: =SUM(AA45:AA46) -> 166074.05 | AC47: =SUM(AC45:AC46) -> 0 | AE47: =SUM(AE45:AE46) -> 560406.87
...

Sheet Material Conversion details
B2: Type | C2: DRG. Material | D2: Alt. Material | G2: Type | H2: Size (mm) | I2: Alternate size (mm) (As per indian availablity) | J2: Remarks
B3: Beam | C3: ASTM A572 Gr. 50 / S355JR | D3: IS 2062 E350 A/BR | G3: Beam | H3: W-BEAM, 190 X 450 | I3: NPB 450x190x 67.16
B4: BOP Unistruct | C4: G40.21-44W / A572 G50 | D4: Gi Sheet 2mm thk | G4: Beam | H4: W-BEAM 600 X 220 | I4: NPB 600x 220x 107.57
B5: Channel | C5: A36/S275JR | D5: IS 2062 E250 A/BR | G5: Channel | H5: UPN 200 x 75 | I5: ISMC 200 x 75
B6: Channel | C6: ASTM A572 Gr. 50 / S355JR | D6: IS 2062 E350 A/BR | G6: Channel | H6: UPN 160 X 65 | I6: ISMC 175x 75 | J6: Or builtup to achive the Dimension as per UPN 160 with suitable thickness and material
B7: Pipe | C7: ASTM A106 GR.B | D7: ASTM A106 GR.B | G7: Channel | H7: UPN 80 X 45 | I7: ISMC 75x40 | J7: Or builtup to achive the Dimension as per UPN 160 with suitable thickness and material
B8: Pipe | C8: G40.21-44W | D8: ASTM A106 GR.B | G8: Rec Tube | H8: 100x80x 5thk | I8: 100x80x6
B9: Pipe | C9: G40.21-44W / A572 G50 | D9: ASTM A106 GR.B | G9: Rec Tube | H9: 120x80x 5thk | I9: 120x80x6.5
B10: Pipe | C10: EN 10216-2 P265GH | D10: ASTM A106 GR.B | G10: Rec Tube | H10: 150x100x 12thk | I10: 150x100x11to12
B11: Plate | C11: ASTM A572 Gr. 50 / A516 Gr.70 / S355JR/ G40.21-44W | D11: IS 2062 E350 A/BR | G11: Rec Tube | H11: 150x80x 10thk | I11: 150x80x9.5 to 10thk
B12: Plate | C12: A36/S275JR/SA 516 GR.70 | D12: IS 2062 E250 A/BR | G12: Rec Tube | H12: 200x150x 12thk | J12: Available as required
B13: Plate | C13: A.S.T.M. A106 GR.B | D13: IS 2062 E350 A/BR | G13: Rec Tube | H13: 150x50x 6thk | J13: Available as required
B14: Plate | C14: EN 10025-2 S355J2 | D14: IS 2062 E350 A/BR | G14: Sq. Tube | H14: 40x40x 5thk | J14: Available as required
B15: Rod | C15: A36/275JR | D15: IS 2062 E250 A/BR | G15: Sq. Tube | H15: 50x50x 5thk | J15: Available as required
B16: Rod | C16: BROWNING SCS-2 | D16: EN 19 | G16: Sq. Tube | H16: 80x80x 10thk | I16: 80x80x 8thk
B17: Rod | C17: AISI C1045 | D17: EN 19 | G17: Pipe | H17: Dia 101.6 x 8.08 thk | J17: Available as required
B18: Rod | C18: A572 Gr. 50 | D18: IS 2062 E350 A/BR | G18: Pipe | H18: Dia 114.3 x 8.56 thk | J18: Available as required
B19: Tube | C19: A36/S275JR | D19: YST 310 | G19: Pipe | H19: Dia 168.28 x 10.97thk | J19: Available as required
B20: Tube | C20: ASTM A516 Gr.70/S275JR | D20: YST 310 | G20: Pipe | H20: Dia 21.3 x 2.77 thk | J20: Available as required
B21: Tube | C21: ASTM A500 GR B | D21: YST 310 | G21: Pipe | H21: Dia 33.4x 6.35 | J21: Available as required
B22: Tube | C22: EN 10025-2 S355J2 | D22: YST 310 | G22: Pipe | H22: Dia 60.3 x 3.91 thk | J22: Available as required

Sheet Item-14_AY30130
A1: COSTING SHEET
A2: PRODUCT NAME:- | B2: ='BOM R2D CatWalk'!I201 -> WELDMENT, PC4100,42' CATWALK, RAMP B | E2: RFQ Ref.
A3: ITEM DRG NO | B3: ='BOM R2D CatWalk'!G201 -> AY30130 | E3: Total Quantity | F3: ='BOM R2D CatWalk'!K201 -> 1
A4: Total Net WT as per Drawing | C4: ='BOM R2D CatWalk'!N201 -> 4003
A5: COSTBREAKUP OF COMPONENT (QTY-01 No.) | J5: Assy No | Q5: ='RM Details'!H183 -> AY30130
A6: RAW MATERIAL COST | J6: S.No | K6: Type | L6: Size (mm) | M6: Material | N6: Sum of Total Weight (Kg) | O6: Sum of Gross Wt (kg) | P6: MOQ Weight | Q6: Remarks | R6: Cal. Weight | S6: Rate/Kg | T6: Cost
A7: SPEC | B7: IS 2062 E350 A/BO | C7: IS 2062 E250 A/BO | D7: YST 310 | E7: =M14 -> AISI C1045 | F7: Rolled Section E350A | J7: 1 | K7: Plate | L7: 6 | M7: E350 A/BR | N7: ='RM Details'!E185 -> 1.6 | O7: ='RM Details'!F185 -> 2.5667192 | R7: =IF(P7>O7,P7,IF(P7<O7,O7)) -> 2.5667192 | S7: 90 | T7: =S7*R7 -> 231.00473
A8: GROSS WT. (KG) | B8: =SUM(O7:O9) -> 1607.8875 | C8: =SUM(O10:O11) -> 259.71541 | D8: =SUM(O12:O13) -> 950.36093 | E8: =O14 -> 13.35774 | F8: =O15+O16 -> 1982.9762 | G8: =SUM(B8:F8) -> 4814.2978 | J8: 2 | K8: Plate | L8: 10 | M8: E350 A/BR | N8: ='RM Details'!E186 -> 978.4 | O8: ='RM Details'!F186 -> 1102.0319 | R8: =IF(P8>O8,P8,IF(P8<O8,O8)) -> 1102.0319 | S8: 90 | T8: =S8*R8 -> 99182.867
A9: NET WT (KG) | B9: =SUM(N7:N9) -> 1231.6685 | C9: =SUM(N10:N11) -> 181.0556 | D9: =SUM(N12:N13) -> 863.96448 | E9: =N14 -> 11.2 | F9: =N15+N16 -> 1798.2208 | G9: =SUM(B9:F9) -> 4086.1094 | J9: 3 | K9: Plate | L9: 12 | M9: E350 A/BR | N9: ='RM Details'!E187 -> 251.66848 | O9: ='RM Details'!F187 -> 503.28897 | R9: =IF(P9>O9,P9,IF(P9<O9,O9)) -> 503.28897 | S9: 90 | T9: =S9*R9 -> 45296.007
A10: SCRAP (KG) | B10: =(B8-B9)*80% -> 300.97526 | C10: =(C8-C9)*80% -> 62.92785 | D10: =(D8-D9)*80% -> 69.117158 | E10: =(E8-E9)*80% -> 1.726192 | F10: =(F8-F9)*80% -> 147.80429 | G10: =(G8-G9)/G9 -> 0.17821071 | J10: 4 | K10: Plate | L10: 12 | M10: E250 A/BR | N10: ='RM Details'!E188 -> 29.9556 | O10: ='RM Details'!F188 -> 32.95116 | R10: =IF(P10>O10,P10,IF(P10<O10,O10)) -> 32.95116 | S10: 90 | T10: =S10*R10 -> 2965.6044
A11: RM RATE (RS/KG) | B11: 90 | C11: 90 | D11: 200 | E11: 150 | F11: 120 | G11: =SUMPRODUCT(B11:F11,B8:F8) -> 598117.25 | J11: 5 | K11: Plate | L11: 20 | M11: E250 A/BR | N11: ='RM Details'!E189 -> 151.1 | O11: ='RM Details'!F189 -> 226.76425 | R11: =IF(P11>O11,P11,IF(P11<O11,O11)) -> 226.76425 | S11: 90 | T11: =S11*R11 -> 20408.783
A12: SCRAP RATE (RS/KG) | B12: 30 | C12: 30 | D12: 30 | E12: 30 | F12: 30 | J12: 6 | K12: Rec Tube | L12: 150x50x 6thk | M12: YST 310 | N12: ='RM Details'!E190 -> 39.95376 | O12: ='RM Details'!F190 -> 43.949136 | P12: =17.71*6 -> 106.26 | R12: =IF(P12>O12,P12,IF(P12<O12,O12)) -> 106.26 | S12: 200 | T12: =S12*R12 -> 21252
A13: NET RM COST (RS) | B13: =(B8*B11)-(B10*B12) -> 135680.62 | C13: =(C8*C11)-(C10*C12) -> 21486.552 | D13: =(D8*D11)-(D10*D12) -> 187998.67 | E13: =(E8*E11)-(E10*E12) -> 1951.8752 | F13: =(F8*F11)-(F10*F12) -> 233523.01 | G13: =SUM(B13:F13) -> 580640.73 | J13: 7 | K13: Rec Tube | L13: 200x150x 12thk | M13: YST 310 | N13: ='RM Details'!E191 -> 824.01072 | O13: ='RM Details'!F191 -> 906.41179 | P13: =61.42*6 -> 368.52 | R13: =IF(P13>O13,P13,IF(P13<O13,O13)) -> 906.41179 | S13: 200 | T13: =S13*R13 -> 181282.36 | U13: =(T12+T13)/(R12+R13) -> 200
A14: TOTAL (RS) | B14: =SUM(B13:F13) -> 580640.73 | G14: =G13/G8 -> 120.60756 | J14: 8 | K14: ROD | L14: Dia 30 | M14: ='RM Details'!D192 -> AISI C1045 | N14: ='RM Details'!E192 -> 11.2 | O14: ='RM Details'!F192 -> 13.35774 | P14: =5.55*1 -> 5.55 | R14: =IF(P14>O14,P14,IF(P14<O14,O14)) -> 13.35774 | S14: 150 | T14: =S14*R14 -> 2003.661
A15: BOP COST | J15: 9 | K15: ROD | L15: Dia 142 | M15: E350 A/BR | N15: ='RM Details'!E193 -> 32.2 | O15: ='RM Details'!F193 -> 49.23072 | P15: =124.32*1 -> 124.32 | R15: =IF(P15>O15,P15,IF(P15<O15,O15)) -> 124.32 | S15: 120 | T15: =S15*R15 -> 14918.4
A16: BOP COST (RS) | J16: 10 | K16: Plate | L16: UPN 160 X 65 X 18.8 | M16: E350 A/BR | N16: ='RM Details'!E194 -> 1766.0208 | O16: ='RM Details'!F194 -> 1933.7454 | P16: =18.8*6 -> 112.8 | R16: =IF(P16>O16,P16,IF(P16<O16,O16)) -> 1933.7454 | S16: 120 | T16: =S16*R16 -> 232049.45
A17: TOTAL BOP | F17: =SUM(F16:F16) -> 0 | L17: Total | N17: =SUM(N7:N16) -> 4086.1094 | O17: =SUM(O7:O16) -> 4814.2978 | R17: =SUM(R7:R16) -> 4951.6979 | S17: =T17/R17 -> 125.1268 | T17: =SUM(T7:T16) -> 619590.14
A18: TOTAL OF RM + BOP (RS) | F18: =B14+F17 -> 580640.73
A19: PROCESS COST
A20: SPEC | B20: QTY | D20: RATE | F20: TOTAL COST
A21: LASER /PLASMA/PIPE - Cutting (Min.) | B21: ='BOM R2D CatWalk'!X201 -> 233.00992 | D21: 50 | F21: =B21*D21 -> 11650.496 | H21: =F21/$G$9 -> 2.8512443
A22: Machining (Hrs) | B22: ='BOM R2D CatWalk'!AB201/60+1 -> 3.3333333 | D22: 1000 | F22: =B22*D22 -> 3333.3333 | H22: =F22/$G$9 -> 0.81577193
A23: BENDING BY CNC BENDING (STROKE) | B23: ='BOM R2D CatWalk'!Z201 -> 12 | D23: 100 | F23: =B23*D23 -> 1200 | H23: =F23/$G$9 -> 0.2936779
A24: MIG WELDING (MTR.) | B24: 502 | D24: 300 | F24: =B24*D24 -> 150600 | H24: =F24/$G$9 -> 36.856576
A25: GRINDING/BUFFING & FINISHING (hrs) | B25: =B24/12.5 -> 40.16 | D25: 250 | F25: =B25*D25 -> 10040 | H25: =F25/$G$9 -> 2.4571051
A26: INSPECTION & TESTING (HRS) | B26: =G9/95 -> 43.011677 | D26: 1200 | F26: =B26*D26 -> 51614.013 | H26: =F26/$G$9 -> 12.631579
A27: STRESS RELIEVING | D27: 250 | F27: =B27*D27 -> 0 | G27: As Actual, If required | H27: =F27/$G$9 -> 0
A28: Shot Blasting | D28: 5 | F28: =D28*G9 -> 20430.547 | H28: =F28/$G$9 -> 5
A29: Hot Dip Galvanization | B29: 0 | D29: 50 | F29: =B29*D29 -> 0 | H29: =F29/$G$9 -> 0
A30: PAINTING (including material & Labor) | B30: ='BOM R2D CatWalk'!AI201 -> 147.17993 | D30: 1200 | F30: =B30*D30 -> 176615.92 | G30: No paint Detail Found | H30: =F30/$G$9 -> 43.223492
A31: Stamping Cost (HRS) | B31: =15/60 -> 0.25 | D31: 250 | F31: =B31*D31 -> 62.5 | H31: =F31/$G$9 -> 0.015295724
A32: FE cost | D32: 4.5 | F32: =D32*G9 -> 18387.492 | H32: =F32/$G$9 -> 4.5
A33: TOTAL PROCESS COST OF PC | F33: =SUM(F21:F32) -> 443934.3 | H33: =F33/$G$9 -> 108.64474
A34: TOTAL RM+BOP+PC | F34: =F18+F33 -> 1024575
A35: OH + Contingency | E35: 0.1 | F35: =F34*E35 -> 102457.5 | H35: =F35/$G$9 -> 25.074587
A36: Total Product Cost Without Profit | F36: =SUM(F34:F35) -> 1127032.5 | H36: =F36/G9 -> 275.82045
G39: Min.
A40: NOTES:- | F40: OTHER COST | G40: Min.
A41: No BOP found in the Drawing Details
A42: Stress relieveing NOT FOUND ON PRINTS, IF REQUIRED | F42: As Actual
...

Sheet Item-13_AY51606
A1: COSTING SHEET
A2: PRODUCT NAME:- | B2: ='BOM R2D CatWalk'!I187 -> KIT, SHIPPING BRKTS, LONG,PC4000 | D2: RFQ Ref.
A3: ITEM DRG NO | B3: ='BOM R2D CatWalk'!G187 -> AY51606 | D3: Total Quantity | E3: ='BOM R2D CatWalk'!K187 -> 1
A4: Total Net WT as per Drawing | B4: ='BOM R2D CatWalk'!N187 -> 175.0738 | J4: Assy No | Q4: ='RM Details'!H172 -> AY51606
A5: COSTBREAKUP OF COMPONENT (QTY-01 No.) | J5: S.No | K5: Type | L5: Size (mm) | M5: Material | N5: Sum of Total Weight (Kg) | O5: Sum of Gross Wt (kg) | P5: MOQ Weight | Q5: Remarks | R5: Cal. Weight | S5: Rate/Kg | T5: Cost
A6: RAW MATERIAL COST | J6: 1 | K6: Plate | L6: 10 | M6: E350 A/BR | N6: ='RM Details'!E174 -> 45.0747 | O6: ='RM Details'!F174 -> 49.58217 | R6: =IF(P6>O6,P6,IF(P6<O6,O6)) -> 49.58217 | S6: 90 | T6: =S6*R6 -> 4462.3953
A7: SPEC | F7: IS 2062: E350 A/BR | J7: 2 | K7: Plate | L7: 12 | M7: E350 A/BR | N7: ='RM Details'!E175 -> 36.854949 | O7: ='RM Details'!F175 -> 43.271712 | R7: =IF(P7>O7,P7,IF(P7<O7,O7)) -> 43.271712 | S7: 90 | T7: =S7*R7 -> 3894.4541
A8: GROSS WT. (KG) | F8: =R9 -> 250.32865 | G8: =SUM(C8:F8) -> 250.32865 | J8: 3 | K8: Plate | L8: 40 | M8: E350 A/BR | N8: ='RM Details'!E176 -> 95.943328 | O8: ='RM Details'!F176 -> 157.47477 | R8: =IF(P8>O8,P8,IF(P8<O8,O8)) -> 157.47477 | S8: 90 | T8: =S8*R8 -> 14172.729
A9: NET WT (KG) | F9: =N9 -> 177.87298 | G9: =SUM(C9:F9) -> 177.87298 | L9: Total | N9: =SUM(N6:N8) -> 177.87298 | O9: =SUM(O6:O8) -> 250.32865 | R9: =SUM(R6:R8) -> 250.32865 | S9: =T9/R9 -> 90 | T9: =SUM(T6:T8) -> 22529.579
A10: SCRAP (KG) | F10: =(F8-F9)*80% -> 57.964538 | G10: =(G8-G9)/G9 -> 0.40734503
A11: RM RATE (RS/KG) | F11: 90 | G11: =SUMPRODUCT(B11:F11,B8:F8) -> 22529.578
A12: SCRAP RATE (RS/KG) | F12: 30
A13: NET RM COST (RS) | F13: =(F8*F11)-(F10*F12) -> 20790.642 | G13: =SUM(B13:F13) -> 20790.642
A14: TOTAL (RS) | B14: =SUM(B13:F13) -> 20790.642 | G14: =G13/G8 -> 83.053387
A15: BOP COST
A16: BOP COST (RS)
A17: TOTAL BOP | F17: =SUM(F16:F16) -> 0
A18: TOTAL OF RM + BOP (RS) | F18: =B14+F17 -> 20790.642
A19: PROCESS COST
A20: SPEC | B20: QTY | C20: RATE | F20: TOTAL COST
A21: LASER /PLASMA/PIPE - Cutting (Min.) | B21: ='BOM R2D CatWalk'!X187 -> 27.447842 | C21: 45 | F21: =B21*C21 -> 1235.1529 | H21: =F21/$G$9 -> 6.9440164
A22: Machining (Hrs) | B22: ='BOM R2D CatWalk'!AB187/60 -> 0.66666667 | C22: 600 | F22: =B22*C22 -> 400 | H22: =F22/$G$9 -> 2.2487958
A23: BENDING BY CNC BENDING (STROKE) | B23: ='BOM R2D CatWalk'!Z187 -> 0 | C23: 100 | F23: =B23*C23 -> 0 | H23: =F23/$G$9 -> 0
A24: MIG WELDING (MTR.) | B24: ='BOM R2D CatWalk'!AF187 -> 13.032 | C24: 250 | F24: =B24*C24 -> 3258 | H24: =F24/$G$9 -> 18.316442
A25: GRINDING/BUFFING & FINISHING (hrs) | B25: =B24/12 -> 1.086 | C25: 250 | F25: =B25*C25 -> 271.5 | H25: =F25/$G$9 -> 1.5263701
A26: INSPECTION & TESTING (HRS) | B26: =G9/95 -> 1.8723471 | C26: 1200 | F26: =B26*C26 -> 2246.8166 | H26: =F26/$G$9 -> 12.631579
A27: STRESS RELIEVING | C27: 250 | F27: =B27*C27 -> 0 | G27: As Actual, If required | H27: =F27/$G$9 -> 0
A28: Shot Blasting | C28: 5 | F28: =C28*G9 -> 889.36489 | H28: =F28/$G$9 -> 5
A29: Hot Dip Galvanization | B29: 0 | C29: 50 | F29: =B29*C29 -> 0 | H29: =F29/$G$9 -> 0
A30: PAINTING (including material & Labor) | B30: ='BOM R2D CatWalk'!AI187 -> 3.329756 | C30: 1250 | F30: =B30*C30 -> 4162.195 | G30: No paint Detail Found | H30: =F30/$G$9 -> 23.399816
A31: Stamping Cost (HRS) | B31: =15/60 -> 0.25 | C31: 250 | F31: =B31*C31 -> 62.5 | H31: =F31/$G$9 -> 0.35137434
A32: FE cost | C32: 4.5 | F32: =C32*G9 -> 800.4284 | H32: =F32/$G$9 -> 4.5
A33: TOTAL PROCESS COST OF PC | F33: =SUM(F21:F32) -> 13325.958 | H33: =F33/$G$9 -> 74.918394
A34: TOTAL RM+BOP+PC | F34: =F18+F33 -> 34116.6
A35: OH + Contingency | D35: 0.1 | F35: =F34*D35 -> 3411.66 | H35: =F35/$G$9 -> 19.180317
A36: Total Product Cost Without Profit | F36: =SUM(F34:F35) -> 37528.26 | H36: =F36/G9 -> 210.98348 | I36: =F36/G8 -> 149.91596
G39: Min.
A40: NOTES:- | F40: OTHER COST | G40: Min.
A41: No BOP found in the Drawing Details
A42: Stress relieveing NOT FOUND ON PRINTS, IF REQUIRED | F42: As Actual
...

Sheet Item-12_AY30160
A1: COSTING SHEET
A2: PRODUCT NAME:- | B2: ='BOM R2D CatWalk'!I171 -> WELDMENT,42D CARRIER REAR, PC4100 | D2: RFQ Ref.
A3: ITEM DRG NO | B3: ='BOM R2D CatWalk'!G171 -> AY30160 | D3: Total Quantity | E3: ='BOM R2D CatWalk'!K171 -> 1
A4: Total Net WT as per Drawing | B4: ='BOM R2D CatWalk'!N171 -> 777 | J4: Assy No | Q4: ='RM Details'!H154 -> AY30160
A5: COSTBREAKUP OF COMPONENT (QTY-01 No.) | J5: S.No | K5: Type | L5: Size (mm) | M5: Material | N5: Sum of Total Weight (Kg) | O5: Sum of Gross Wt (kg) | P5: MOQ Weight | Q5: Remarks | R5: Cal. Weight | S5: Rate/Kg | T5: Cost
A6: RAW MATERIAL COST | J6: 1 | K6: Plate | L6: 6 | M6: E350 A/BR | N6: ='RM Details'!E156 -> 1.2 | O6: ='RM Details'!F156 -> 1.2045825 | R6: =IF(P6>O6,P6,IF(P6<O6,O6)) -> 1.2045825 | S6: 90 | T6: =S6*R6 -> 108.41243
A7: SPEC | B7: IS 2062: E350 A/BR | C7: IS 2062: E250 A/BR | D7: YST 310 | E7: =M13 -> AISI C1045 | F7: Rolled Section E350A/BR | J7: 2 | K7: Plate | L7: 10 | M7: E350 A/BR | N7: ='RM Details'!E157 -> 46 | O7: ='RM Details'!F157 -> 68.055025 | R7: =IF(P7>O7,P7,IF(P7<O7,O7)) -> 68.055025 | S7: 90 | T7: =S7*R7 -> 6124.9523
A8: GROSS WT. (KG) | B8: =SUM(R6:R9) -> 269.88996 | C8: =SUM(R10:R11) -> 99.897452 | D8: =R12 -> 368.52 | E8: =R13 -> 31.96 | F8: =R14 -> 531.9072 | G8: =SUM(C8:F8) -> 1032.2847 | J8: 3 | K8: Plate | L8: 12 | M8: E350 A/BR | N8: ='RM Details'!E158 -> 149.6 | O8: ='RM Details'!F158 -> 199.55098 | R8: =IF(P8>O8,P8,IF(P8<O8,O8)) -> 199.55098 | S8: 90 | T8: =S8*R8 -> 17959.588
A9: NET WT (KG) | B9: =SUM(N6:N9) -> 197.78125 | C9: =SUM(N10:N11) -> 71 | D9: =N12 -> 25 | E9: =N13 -> 1.6 | F9: =N14 -> 482 | G9: =SUM(C9:F9) -> 579.6 | J9: 3 | K9: Plate | L9: 25 | M9: E350 A/BR | N9: ='RM Details'!E159 -> 0.98125 | O9: ='RM Details'!F159 -> 1.079375 | R9: =IF(P9>O9,P9,IF(P9<O9,O9)) -> 1.079375 | S9: 90 | T9: =S9*R9 -> 97.14375
A10: SCRAP (KG) | B10: =(B8-B9)*80% -> 57.686972 | C10: =(C8-C9)*80% -> 23.117961 | D10: =(D8-D9)*80% -> 274.816 | E10: =(E8-E9)*80% -> 24.288 | F10: =(F8-F9)*80% -> 39.92576 | G10: =(G8-G9)/G9 -> 0.78102942 | J10: 4 | K10: Plate | L10: 20 | M10: E250 A/BR | N10: ='RM Details'!E160 -> 47 | O10: ='RM Details'!F160 -> 54.871971 | R10: =IF(P10>O10,P10,IF(P10<O10,O10)) -> 54.871971 | S10: 90 | T10: =S10*R10 -> 4938.4774
A11: RM RATE (RS/KG) | B11: 90 | C11: 90 | D11: 200 | E11: 110 | F11: 110 | G11: =SUMPRODUCT(B11:F11,B8:F8) -> 169010.26 | J11: 5 | K11: Plate | L11: 25 | M11: E250 A/BR | N11: ='RM Details'!E161 -> 24 | O11: ='RM Details'!F161 -> 45.025481 | R11: =IF(P11>O11,P11,IF(P11<O11,O11)) -> 45.025481 | S11: 90 | T11: =S11*R11 -> 4052.2932
A12: SCRAP RATE (RS/KG) | B12: 30 | C12: 30 | D12: 30 | E12: 30 | F12: 30 | J12: 6 | K12: Plate | L12: 200 X 150 X 12thk | M12: YST 310 | N12: ='RM Details'!E162 -> 25 | O12: ='RM Details'!F162 -> 38.84815 | P12: =61.42*6 -> 368.52 | R12: =IF(P12>O12,P12,IF(P12<O12,O12)) -> 368.52 | S12: 200 | T12: =S12*R12 -> 73704
A13: NET RM COST (RS) | B13: =(B8*B11)-(B10*B12) -> 22559.488 | C13: =(C8*C11)-(C10*C12) -> 8297.2318 | D13: =(D8*D11)-(D10*D12) -> 65459.52 | E13: =(E8*E11)-(E10*E12) -> 2786.96 | F13: =(F8*F11)-(F10*F12) -> 57312.019 | G13: =SUM(B13:F13) -> 156415.22 | J13: 7 | K13: Plate | L13: Dia 72 | M13: AISI C1045 | N13: ='RM Details'!E163 -> 1.6 | O13: ='RM Details'!F163 -> 1.76 | P13: =31.96*1 -> 31.96 | R13: =IF(P13>O13,P13,IF(P13<O13,O13)) -> 31.96 | S13: 110 | T13: =S13*R13 -> 3515.6
A14: TOTAL (RS) | B14: =SUM(B13:F13) -> 156415.22 | G14: =G13/G8 -> 151.52334 | J14: 8 | K14: Plate | L14: NPB 450x190x67.16 | M14: IS 2062 E 350 A | N14: ='RM Details'!E164 -> 482 | O14: ='RM Details'!F164 -> 531.9072 | P14: =67.16*6 -> 402.96 | R14: =IF(P14>O14,P14,IF(P14<O14,O14)) -> 531.9072 | S14: 110 | T14: =S14*R14 -> 58509.792
A15: BOP COST | L15: Total | N15: =SUM(N6:N14) -> 777.38125 | O15: =SUM(O6:O14) -> 942.30277 | R15: =SUM(R6:R14) -> 1302.1746 | S15: =T15/R15 -> 129.79078 | T15: =SUM(T6:T14) -> 169010.26
A16: BOP COST (RS)
A17: TOTAL BOP | F17: =SUM(F16:F16) -> 0
A18: TOTAL OF RM + BOP (RS) | F18: =B14+F17 -> 156415.22
A19: PROCESS COST
A20: SPEC | B20: QTY | C20: RATE | F20: TOTAL COST
A21: LASER /PLASMA/PIPE - Cutting (Min.) | B21: ='BOM R2D CatWalk'!X171 -> 94.168469 | C21: 30 | F21: =B21*C21 -> 2825.0541 | H21: =F21/$G$9 -> 4.8741444
A22: Machining (Hrs) | B22: ='BOM R2D CatWalk'!AB171/60 -> 4.3166667 | C22: 1250 | F22: =B22*C22 -> 5395.8333 | H22: =F22/$G$9 -> 9.3095813
A23: BENDING BY CNC BENDING (STROKE) | B23: ='BOM R2D CatWalk'!Z171 -> 3 | C23: 100 | F23: =B23*C23 -> 300 | H23: =F23/$G$9 -> 0.51759834
A24: MIG WELDING (MTR.) | B24: 71.2 | C24: 250 | F24: =B24*C24 -> 17800 | H24: =F24/$G$9 -> 30.710835
A25: GRINDING/BUFFING & FINISHING (hrs) | B25: =B24/12 -> 5.9333333 | C25: 250 | F25: =B25*C25 -> 1483.3333 | H25: =F25/$G$9 -> 2.5592363
A26: INSPECTION & TESTING (HRS) | B26: =G9/95 -> 6.1010526 | C26: 1200 | F26: =B26*C26 -> 7321.2632 | H26: =F26/$G$9 -> 12.631579
A27: STRESS RELIEVING | C27: 250 | F27: =B27*C27 -> 0 | G27: As Actual, If required | H27: =F27/$G$9 -> 0
A28: Shot Blasting | C28: 5 | F28: =C28*G9 -> 2898 | H28: =F28/$G$9 -> 5
A29: Hot Dip Galvanization | B29: 0 | C29: 50 | F29: =B29*C29 -> 0 | H29: =F29/$G$9 -> 0
A30: PAINTING (including material & Labor) | B30: ='BOM R2D CatWalk'!AI171 -> 8.1248013 | C30: 1250 | F30: =B30*C30 -> 10156.002 | G30: No paint Detail Found | H30: =F30/$G$9 -> 17.522432
A31: Stamping Cost (HRS) | B31: =15/60 -> 0.25 | C31: 250 | F31: =B31*C31 -> 62.5 | H31: =F31/$G$9 -> 0.10783299
A32: FE cost | C32: 4.5 | F32: =C32*G9 -> 2608.2 | H32: =F32/$G$9 -> 4.5
A33: TOTAL PROCESS COST OF PC | F33: =SUM(F21:F32) -> 50850.186 | H33: =F33/$G$9 -> 87.733239
A34: TOTAL RM+BOP+PC | F34: =F18+F33 -> 207265.4
A35: OH + Contingency | D35: 0.1 | F35: =F34*D35 -> 20726.54 | H35: =F35/$G$9 -> 35.760077
A36: Total Product Cost Without Profit | F36: =SUM(F34:F35) -> 227991.94 | H36: =F36/G9 -> 393.36084 | I36: =F36/G8 -> 220.86151
G39: Min.
A40: NOTES:- | F40: OTHER COST | G40: Min.
A41: No BOP found in the Drawing Details
A42: Stress relieveing NOT FOUND ON PRINTS, IF REQUIRED | F42: As Actual
...

Sheet Item-11_AT30150
A1: COSTING SHEET
A2: PRODUCT NAME:- | B2: ='BOM R2D CatWalk'!I162 -> WELDMENT, SPEAR FRAME, PC4100 | D2: RFQ Ref.
A3: ITEM DRG NO | B3: ='BOM R2D CatWalk'!G162 -> AY30150 | D3: Total Quantity | E3: ='BOM R2D CatWalk'!K162 -> 1
A4: Total Net WT as per Drawing | B4: ='BOM R2D CatWalk'!N162 -> 69 | J4: Assy No | Q4: ='RM Details'!H141 -> AY30150
A5: COSTBREAKUP OF COMPONENT (QTY-01 No.) | J5: S.No | K5: Type | L5: Size (mm) | M5: Material | N5: Sum of Total Weight (Kg) | O5: Sum of Gross Wt (kg) | P5: MOQ Weight | Q5: Remarks | R5: Cal. Weight | S5: Rate/Kg | T5: Cost
A6: RAW MATERIAL COST | J6: 1 | K6: Plate | L6: 12 | M6: E350 A/BR | N6: ='RM Details'!E143 -> 4.4 | O6: ='RM Details'!F143 -> 8.4330101 | R6: =IF(P6>O6,P6,IF(P6<O6,O6)) -> 8.4330101 | S6: 90 | T6: =S6*R6 -> 758.97091
A7: SPEC | C7: IS 2062: E350 A/BR | D7: IS 2062: E250 A/BR | E7: YST 310 | F7: ROD E250A/BR | J7: 2 | K7: Pipe | L7: 20 | M7: E250 A/BR | N7: ='RM Details'!E144 -> 6 | O7: ='RM Details'!F144 -> 12.841972 | R7: =IF(P7>O7,P7,IF(P7<O7,O7)) -> 12.841972 | S7: 90 | T7: =S7*R7 -> 1155.7775
A8: GROSS WT. (KG) | C8: =R6 -> 8.4330101 | D8: =R7 -> 12.841972 | E8: =R8 -> 77.04 | F8: =R9 -> 2.67 | G8: =SUM(C8:F8) -> 100.98498 | J8: 3 | K8: Plate | L8: 120x80x 5thk 120x60x 5thk | M8: YST 310 | N8: ='RM Details'!E145 -> 54.73 | O8: ='RM Details'!F145 -> 60.203 | P8: =12.84*6 -> 77.04 | R8: =IF(P8>O8,P8,IF(P8<O8,O8)) -> 77.04 | S8: 110 | T8: =S8*R8 -> 8474.4
A9: NET WT (KG) | C9: =N6 -> 4.4 | D9: =N7 -> 6 | E9: =N8 -> 54.73 | F9: =N9 -> 0.4 | G9: =SUM(C9:F9) -> 65.53 | J9: 4 | K9: Plate | L9: Dia 12 | M9: E250 A/BR | N9: ='RM Details'!E146 -> 0.4 | O9: ='RM Details'!F146 -> 2.509364 | P9: =0.89*3 -> 2.67 | R9: =IF(P9>O9,P9,IF(P9<O9,O9)) -> 2.67 | S9: 110 | T9: =S9*R9 -> 293.7
A10: SCRAP (KG) | C10: =(C8-C9)*80% -> 3.2264081 | D10: =(D8-D9)*80% -> 5.4735776 | E10: =(E8-E9)*80% -> 17.848 | F10: =(F8-F9)*80% -> 1.816 | G10: =(G8-G9)/G9 -> 0.54104963 | L10: Total | N10: =SUM(N6:N9) -> 65.53 | O10: =SUM(O6:O9) -> 83.987346 | R10: =SUM(R6:R9) -> 100.98498 | S10: =T10/R10 -> 105.78651 | T10: =SUM(T6:T9) -> 10682.848
A11: RM RATE (RS/KG) | C11: 90 | D11: 90 | E11: 200 | F11: 110 | G11: =SUMPRODUCT(B11:F11,B8:F8) -> 17616.448
A12: SCRAP RATE (RS/KG) | C12: 30 | D12: 30 | E12: 30 | F12: 30
A13: NET RM COST (RS) | C13: =(C8*C11)-(C10*C12) -> 662.17867 | D13: =(D8*D11)-(D10*D12) -> 991.57015 | E13: =(E8*E11)-(E10*E12) -> 14872.56 | F13: =(F8*F11)-(F10*F12) -> 239.22 | G13: =SUM(B13:F13) -> 16765.529
A14: TOTAL (RS) | B14: =SUM(B13:F13) -> 16765.529 | G14: =G13/G8 -> 166.02002
A15: BOP COST
A16: BOP COST (RS)
A17: TOTAL BOP | F17: =SUM(F16:F16) -> 0
A18: TOTAL OF RM + BOP (RS) | F18: =B14+F17 -> 16765.529
A19: PROCESS COST
A20: SPEC | B20: QTY | C20: RATE | F20: TOTAL COST
A21: LASER /PLASMA/PIPE - Cutting (Min.) | B21: ='BOM R2D CatWalk'!X162 -> 22.320642 | C21: 35 | F21: =B21*C21 -> 781.22248 | H21: =F21/$G$9 -> 11.921601
A22: Machining (Hrs) | B22: ='BOM R2D CatWalk'!AB162/60 -> 0.5 | C22: 1000 | F22: =B22*C22 -> 500 | H22: =F22/$G$9 -> 7.6300931
A23: BENDING BY CNC BENDING (STROKE) | B23: ='BOM R2D CatWalk'!Z162 -> 4 | C23: 50 | F23: =B23*C23 -> 200 | H23: =F23/$G$9 -> 3.0520372
A24: MIG WELDING (MTR.) | B24: ='BOM R2D CatWalk'!AF162 -> 5.6616 | C24: 250 | F24: =B24*C24 -> 1415.4 | H24: =F24/$G$9 -> 21.599268
A25: GRINDING/BUFFING & FINISHING (hrs) | B25: =B24/12 -> 0.4718 | C25: 250 | F25: =B25*C25 -> 117.95 | H25: =F25/$G$9 -> 1.799939
A26: INSPECTION & TESTING (HRS) | B26: =G9/95 -> 0.68978947 | C26: 1200 | F26: =B26*C26 -> 827.74737 | H26: =F26/$G$9 -> 12.631579
A27: STRESS RELIEVING | C27: 250 | F27: =B27*C27 -> 0 | G27: As Actual, If required | H27: =F27/$G$9 -> 0
A28: Shot Blasting | C28: 5 | F28: =C28*G9 -> 327.65 | H28: =F28/$G$9 -> 5
A29: Hot Dip Galvanization | B29: 0 | C29: 50 | F29: =B29*C29 -> 0 | H29: =F29/$G$9 -> 0
A30: PAINTING (including material & Labor) | B30: ='BOM R2D CatWalk'!AI162 -> 2.2032753 | C30: 1250 | F30: =B30*C30 -> 2754.0941 | G30: No paint Detail Found | H30: =F30/$G$9 -> 42.027988
A31: Stamping Cost (HRS) | B31: =15/60 -> 0.25 | C31: 250 | F31: =B31*C31 -> 62.5 | H31: =F31/$G$9 -> 0.95376164
A32: FE cost | C32: 4.5 | F32: =C32*G9 -> 294.885 | H32: =F32/$G$9 -> 4.5
A33: TOTAL PROCESS COST OF PC | F33: =SUM(F21:F32) -> 7281.4489 | H33: =F33/$G$9 -> 111.11627
A34: TOTAL RM+BOP+PC | F34: =F18+F33 -> 24046.978
A35: OH + Contingency | D35: 0.1 | F35: =F34*D35 -> 2404.6978 | H35: =F35/$G$9 -> 36.696136
A36: Total Product Cost Without Profit | F36: =SUM(F34:F35) -> 26451.676 | H36: =F36/G9 -> 403.65749 | I36: =F36/G8 -> 261.93673
G39: Min.
A40: NOTES:- | F40: OTHER COST | G40: Min.
A41: No BOP found in the Drawing Details
A42: Stress relieveing NOT FOUND ON PRINTS, IF REQUIRED | F42: As Actual
...

Sheet Item-10_AT30144
A1: COSTING SHEET
A2: PRODUCT NAME:- | B2: ='BOM R2D CatWalk'!I145 -> WELDMENT, 30 FT LIFT ARM, PC4100 | D2: RFQ Ref.
A3: ITEM DRG NO | B3: ='BOM R2D CatWalk'!G145 -> AY30144 | D3: Total Quantity | E3: ='BOM R2D CatWalk'!K145 -> 1
A4: Total Net WT as per Drawing | B4: ='BOM R2D CatWalk'!N145 -> 1095 | J4: Assy No | Q4: ='RM Details'!H123 -> AY30144
A5: COSTBREAKUP OF COMPONENT (QTY-01 No.) | J5: S.No | K5: Type | L5: Size (mm) | M5: Material | N5: Sum of Total Weight (Kg) | O5: Sum of Gross Wt (kg) | P5: MOQ Weight | Q5: Remarks | R5: Cal. Weight | S5: Rate/Kg | T5: Cost
A6: RAW MATERIAL COST | J6: 1 | K6: Plate | L6: 6 | M6: E250 A/BR | N6: ='RM Details'!E125 -> 1.173732 | O6: ='RM Details'!F125 -> 1.2911052 | R6: =IF(P6>O6,P6,IF(P6<O6,O6)) -> 1.2911052 | S6: 100 | T6: =S6*R6 -> 129.11052
A7: SPEC | B7: IS 2062: E250 A/BR | C7: IS 2062: E350 A/BR | D7: YST 310 | E7: ASTM A106 GR.B | F7: BROWNING SCS-2 | J7: 5 | K7: Pipe | L7: 25 | M7: E250 A/BR | N7: ='RM Details'!E126 -> 104 | O7: ='RM Details'!F126 -> 154.3938 | R7: =IF(P7>O7,P7,IF(P7<O7,O7)) -> 154.3938 | S7: 90 | T7: =S7*R7 -> 13895.442
A8: GROSS WT. (KG) | B8: =R6+R7 -> 155.68491 | C8: =R8+R9+R10 -> 149.76233 | D8: =R11+R12 -> 935.6867 | E8: =R13 -> 110.8866 | F8: =R14 -> 35.61 | G8: =SUM(C8:F8) -> 1231.9456 | J8: 2 | K8: Plate | L8: 10 | M8: E350 A/BR | N8: ='RM Details'!E127 -> 85.73485 | O8: ='RM Details'!F127 -> 138.76549 | R8: =IF(P8>O8,P8,IF(P8<O8,O8)) -> 138.76549 | S8: 90 | T8: =S8*R8 -> 12488.894
A9: NET WT (KG) | B9: =N6+N7 -> 105.17373 | C9: =N8+N9+N10 -> 90.64205 | D9: =N11+N12 -> 850.62427 | E9: =N13 -> 100.806 | F9: =N14 -> 2.4 | G9: =SUM(C9:F9) -> 1044.4723 | J9: 3 | K9: Plate | L9: 12 | M9: E350 A/BR | N9: ='RM Details'!E128 -> 4 | O9: ='RM Details'!F128 -> 4.787244 | R9: =IF(P9>O9,P9,IF(P9<O9,O9)) -> 4.787244 | S9: 100 | T9: =S9*R9 -> 478.7244
A10: SCRAP (KG) | B10: =(B8-B9)*80% -> 40.408939 | C10: =(C8-C9)*80% -> 47.296225 | D10: =(D8-D9)*80% -> 68.049942 | E10: =(E8-E9)*80% -> 8.06448 | F10: =(F8-F9)*80% -> 26.568 | G10: =(G8-G9)/G9 -> 0.17949093 | J10: 4 | K10: Plate | L10: 20 | M10: E350 A/BR | N10: ='RM Details'!E129 -> 0.9072 | O10: ='RM Details'!F129 -> 6.2096012 | R10: =IF(P10>O10,P10,IF(P10<O10,O10)) -> 6.2096012 | S10: 100 | T10: =S10*R10 -> 620.96012
A11: RM RATE (RS/KG) | B11: 90 | C11: 90 | D11: 200 | E11: 130 | F11: 150 | G11: =SUMPRODUCT(B11:F11,B8:F8) -> 234384.35 | J11: 6 | K11: Rec Tube | L11: 150 X 100 X 12thk 150x100x 8thk | M11: YST 310 | N11: ='RM Details'!E130 -> 739.35912 | O11: ='RM Details'!F130 -> 813.29503 | P11: =28.1*6 -> 168.6 | Q11: Apollo | R11: =IF(P11>O11,P11,IF(P11<O11,O11)) -> 813.29503 | S11: 110 | T11: =S11*R11 -> 89462.454
A12: SCRAP RATE (RS/KG) | B12: 30 | C12: 30 | D12: 30 | E12: 30 | F12: 30 | J12: 7 | K12: Rec Tube | L12: 150x80x 10thk 150x100x 8thk | M12: YST 310 | N12: ='RM Details'!E131 -> 111.26515 | O12: ='RM Details'!F131 -> 122.39167 | P12: =28.1*6 -> 168.6 | Q12: Apollo | R12: =O12 -> 122.39167 | S12: 110 | T12: =S12*R12 -> 13463.083
A13: NET RM COST (RS) | B13: =(B8*B11)-(B10*B12) -> 12799.373 | C13: =(C8*C11)-(C10*C12) -> 12059.723 | D13: =(D8*D11)-(D10*D12) -> 185095.84 | E13: =(E8*E11)-(E10*E12) -> 14173.324 | F13: =(F8*F11)-(F10*F12) -> 4544.46 | G13: =SUM(B13:F13) -> 228672.72 | J13: 8 | K13: Pipe | L13: Dia 33.4x 6.35 | M13: ASTM A106 GR.B | N13: ='RM Details'!E132 -> 100.806 | O13: ='RM Details'!F132 -> 110.8866 | P13: =4.24*6 -> 25.44 | Q13: Yash | R13: =IF(P13<O13,O13,IF(P13>O13,P13)) -> 110.8866 | S13: 130 | T13: =S13*R13 -> 14415.258
A14: TOTAL (RS) | B14: =SUM(B13:F13) -> 228672.72 | G14: =G13/G8 -> 185.61917 | J14: 9 | K14: Rod | L14: Dia 76 | M14: BROWNING SCS-2 | N14: ='RM Details'!E133 -> 2.4 | O14: ='RM Details'!F133 -> 2.64 | P14: =35.61*1 -> 35.61 | R14: =IF(P14<O14,O14,IF(P14>O14,P14)) -> 35.61 | S14: 250 | T14: =S14*R14 -> 8902.5
A15: BOP COST | L15: Total | N15: =SUM(N6:N14) -> 1149.6461 | O15: =SUM(O6:O14) -> 1354.6605 | R15: =SUM(R6:R14) -> 1387.6305 | S15: =T15/R15 -> 110.87708 | T15: =SUM(T6:T14) -> 153856.43
A16: BOP COST (RS)
A17: TOTAL BOP | F17: =SUM(F16:F16) -> 0
A18: TOTAL OF RM + BOP (RS) | F18: =B14+F17 -> 228672.72
A19: PROCESS COST
A20: SPEC | B20: QTY | C20: RATE | F20: TOTAL COST
A21: LASER /PLASMA/PIPE - Cutting (Min.) | B21: ='BOM R2D CatWalk'!X145 -> 85.7114 | C21: 35 | F21: =B21*C21 -> 2999.899 | H21: =F21/$G$9 -> 2.8721671
A22: Machining (Hrs) | B22: ='BOM R2D CatWalk'!AB145/60 -> 4.1666667 | C22: 1000 | F22: =B22*C22 -> 4166.6667 | H22: =F22/$G$9 -> 3.9892552
A23: BENDING BY CNC BENDING (STROKE) | B23: ='BOM R2D CatWalk'!Z145 -> 0 | C23: 100 | F23: =B23*C23 -> 0 | H23: =F23/$G$9 -> 0
A24: MIG WELDING (MTR.) | B24: 132 | C24: 250 | F24: =B24*C24 -> 33000 | H24: =F24/$G$9 -> 31.594901
A25: GRINDING/BUFFING & FINISHING (hrs) | B25: =B24/12 -> 11 | C25: 250 | F25: =B25*C25 -> 2750 | H25: =F25/$G$9 -> 2.6329085
A26: INSPECTION & TESTING (HRS) | B26: =G9/95 -> 10.994445 | C26: 1200 | F26: =B26*C26 -> 13193.335 | H26: =F26/$G$9 -> 12.631579
A27: STRESS RELIEVING | C27: 250 | F27: =B27*C27 -> 0 | G27: As Actual, If required | H27: =F27/$G$9 -> 0
A28: Shot Blasting | C28: 5 | F28: =C28*G9 -> 5222.3616 | H28: =F28/$G$9 -> 5
A29: Hot Dip Galvanization | B29: 0 | C29: 50 | F29: =B29*C29 -> 0 | H29: =F29/$G$9 -> 0
A30: PAINTING (including material & Labor) | B30: ='BOM R2D CatWalk'!AI145 -> 21.38217 | C30: 1250 | F30: =B30*C30 -> 26727.712 | G30: No paint Detail Found | H30: =F30/$G$9 -> 25.58968
A31: Stamping Cost (HRS)/Straightning | B31: 4 | C31: 250 | F31: =B31*C31 -> 1000 | H31: =F31/$G$9 -> 0.95742126
A32: FE cost | C32: 4.5 | F32: =C32*G9 -> 4700.1254 | H32: =F32/$G$9 -> 4.5
A33: TOTAL PROCESS COST OF PC | F33: =SUM(F21:F32) -> 93760.099 | H33: =F33/$G$9 -> 89.767912
A34: TOTAL RM+BOP+PC | F34: =F18+F33 -> 322432.82
A35: OH + Contingency | D35: 0.1 | F35: =F34*D35 -> 32243.282 | H35: =F35/$G$9 -> 30.870404
A36: Total Product Cost Without Profit | F36: =SUM(F34:F35) -> 354676.1 | H36: =F36/G9 -> 339.57444 | I36: =F36/G8 -> 287.89915
G39: Min.
A40: NOTES:- Joint need to make while welding | F40: OTHER COST | G40: Min.
A41: No BOP found in the Drawing Details
A42: Stress relieveing NOT FOUND ON PRINTS, IF REQUIRED | F42: As Actual
...

Sheet Item-9_AT30134
A1: COSTING SHEET
A2: PRODUCT NAME:- | B2: ='BOM R2D CatWalk'!I128 -> WELDMENT, RAMP, SHEAVE SUB B, PC4100 | D2: RFQ Ref.
A3: ITEM DRG NO | B3: ='BOM R2D CatWalk'!G128 -> AY30134 | D3: Total Quantity | E3: ='BOM R2D CatWalk'!K128 -> 1
A4: Total Net WT as per Drawing | B4: ='BOM R2D CatWalk'!N128 -> 363 | I4: Assy No | P4: ='RM Details'!H108 -> AY30134
A5: COSTBREAKUP OF COMPONENT (QTY-01 No.) | I5: S.No | J5: Type | K5: Size (mm) | L5: Material | M5: Sum of Total Weight (Kg) | N5: Sum of Gross Wt (kg) | O5: MOQ Weight | P5: Remarks | Q5: Cal. Weight | R5: Rate/Kg | S5: Cost
A6: RAW MATERIAL COST | I6: 1 | J6: Plate | K6: 12 | L6: E350 A/BR | M6: ='RM Details'!E110 -> 96.257444 | N6: ='RM Details'!F110 -> 153.65012 | Q6: =IF(O6>N6,O6,IF(O6<N6,N6)) -> 153.65012 | R6: 90 | S6: =R6*Q6 -> 13828.511
A7: SPEC | C7: IS 2062: E350 A/BR | D7: IS 2062: E250 A/BR | E7: ASTM A106 GR.B | I7: 2 | J7: Plate | K7: 20 | L7: E350 A/BR | M7: ='RM Details'!E111 -> 168.89231 | N7: ='RM Details'!F111 -> 387.04488 | Q7: =IF(O7>N7,O7,IF(O7<N7,N7)) -> 387.04488 | R7: 90 | S7: =R7*Q7 -> 34834.039
A8: GROSS WT. (KG) | C8: =Q6+Q7 -> 540.695 | D8: =Q8+Q9 -> 71.611782 | E8: =Q10+Q11 -> 288 | F8: =SUM(C8:E8) -> 900.30678 | I8: 3 | J8: Plate | K8: 20 | L8: E250 A/BR | M8: ='RM Details'!E112 -> 42 | N8: ='RM Details'!F112 -> 63.824739 | Q8: =IF(O8>N8,O8,IF(O8<N8,N8)) -> 63.824739 | R8: 90 | S8: =R8*Q8 -> 5744.2265
A9: NET WT (KG) | C9: =M6+M7 -> 265.14975 | D9: =M8+M9 -> 46.6 | E9: =M10+M11 -> 58.676352 | F9: =SUM(C9:E9) -> 370.42611 | I9: 4 | J9: Plate | K9: 25 | L9: E250 A/BR | M9: ='RM Details'!E113 -> 4.6 | N9: ='RM Details'!F113 -> 7.787043 | Q9: =IF(O9>N9,O9,IF(O9<N9,N9)) -> 7.787043 | R9: 90 | S9: =R9*Q9 -> 700.83387
A10: SCRAP (KG) | C10: =(C8-C9)*80% -> 220.43619 | D10: =(D8-D9)*80% -> 20.009426 | E10: =(E8-E9)*80% -> 183.45892 | F10: =(F8-F9)/F9 -> 1.4304626 | I10: 5 | J10: Pipe | K10: Dia 168.28 x 10.97thk | L10: ASTM A106 GR.B | M10: ='RM Details'!E114 -> 58.4 | N10: ='RM Details'!F114 -> 64.24 | O10: =42.56*6 -> 255.36 | Q10: =IF(O10>N10,O10,IF(O10<N10,N10)) -> 255.36 | R10: 110 | S10: =R10*Q10 -> 28089.6
A11: RM RATE (RS/KG) | C11: 90 | D11: 90 | E11: 110 | F11: =SUMPRODUCT(B11:E11,B8:E8) -> 86787.61 | I11: 6 | J11: Pipe | K11: Dia 60.3 x 3.91 thk | L11: ASTM A106 GR.B | M11: ='RM Details'!E115 -> 0.276352 | N11: ='RM Details'!F115 -> 0.3039872 | O11: =5.44*6 -> 32.64 | Q11: =IF(O11>N11,O11,IF(O11<N11,N11)) -> 32.64 | R11: 110 | S11: =R11*Q11 -> 3590.4
A12: SCRAP RATE (RS/KG) | C12: 30 | D12: 30 | E12: 30 | K12: Total | M12: =SUM(M6:M11) -> 370.42611 | N12: =SUM(N6:N11) -> 676.85077 | Q12: =SUM(Q6:Q11) -> 900.30678 | R12: =S12/Q12 -> 96.397819 | S12: =SUM(S6:S11) -> 86787.61
A13: NET RM COST (RS) | C13: =(C8*C11)-(C10*C12) -> 42049.464 | D13: =(D8*D11)-(D10*D12) -> 5844.7776 | E13: =(E8*E11)-(E10*E12) -> 26176.232 | F13: =SUM(B13:E13) -> 74070.474
A14: TOTAL (RS) | B14: =SUM(B13:E13) -> 74070.474 | F14: =F13/F8 -> 82.272483
A15: BOP COST
A16: BOP COST (RS)
A17: TOTAL BOP | E17: =SUM(E16:E16) -> 0
A18: TOTAL OF RM + BOP (RS) | E18: =B14+E17 -> 74070.474
A19: PROCESS COST
A20: SPEC | B20: QTY | C20: RATE | E20: TOTAL COST
A21: LASER /PLASMA/PIPE - Cutting (Min.) | B21: ='BOM R2D CatWalk'!X128 -> 37.583277 | C21: 35 | E21: =B21*C21 -> 1315.4147 | G21: =E21/$F$9 -> 3.5510853
A22: Machining (Hrs) | B22: ='BOM R2D CatWalk'!AB128/60 -> 3 | C22: 2000 | E22: =B22*C22 -> 6000 | G22: =E22/$F$9 -> 16.197562
A23: BENDING BY CNC BENDING (STROKE) | B23: ='BOM R2D CatWalk'!Z128 -> 0 | C23: 100 | E23: =B23*C23 -> 0 | G23: =E23/$F$9 -> 0
A24: MIG WELDING (MTR.) | B24: 45 | C24: 300 | E24: =B24*C24 -> 13500 | G24: =E24/$F$9 -> 36.444516
A25: GRINDING/BUFFING & FINISHING (hrs) | B25: =B24/12 -> 3.75 | C25: 250 | E25: =B25*C25 -> 937.5 | G25: =E25/$F$9 -> 2.5308691
A26: INSPECTION & TESTING (HRS) | B26: =F9/95 -> 3.8992222 | C26: 1200 | E26: =B26*C26 -> 4679.0666 | G26: =E26/$F$9 -> 12.631579
A27: STRESS RELIEVING | C27: 250 | E27: =B27*C27 -> 0 | F27: As Actual, If required | G27: =E27/$F$9 -> 0
A28: Shot Blasting | C28: 5 | E28: =C28*F9 -> 1852.1305 | G28: =E28/$F$9 -> 5
A29: Hot Dip Galvanization | B29: 0 | C29: 50 | E29: =B29*C29 -> 0 | G29: =E29/$F$9 -> 0
A30: PAINTING (including material & Labor) | B30: ='BOM R2D CatWalk'!AI128 -> 10.366096 | C30: 1250 | E30: =B30*C30 -> 12957.62 | F30: No paint Detail Found | G30: =E30/$F$9 -> 34.980309
A31: Stamping Cost (HRS) | B31: =15/60 -> 0.25 | C31: 250 | E31: =B31*C31 -> 62.5 | G31: =E31/$F$9 -> 0.16872461
A32: FE cost | C32: 4.5 | E32: =C32*F9 -> 1666.9175 | G32: =E32/$F$9 -> 4.5
A33: TOTAL PROCESS COST OF PC | E33: =SUM(E21:E32) -> 42971.149 | G33: =E33/$F$9 -> 116.00465
A34: TOTAL RM+BOP+PC | E34: =E18+E33 -> 117041.62
A35: OH + Contingency | D35: 0.1 | E35: =E34*D35 -> 11704.162 | G35: =E35/$F$9 -> 31.596483
A36: Total Product Cost Without Profit | E36: =SUM(E34:E35) -> 128745.79 | G36: =E36/F9 -> 347.56132 | H36: =E36/F8 -> 143.00213
F39: Min.
A40: NOTES:- | E40: OTHER COST | F40: Min.
A41: No BOP found in the Drawing Details
A42: Stress relieveing NOT FOUND ON PRINTS, IF REQUIRED | E42: As Actual
...

Sheet Item-8_AT30133
A1: COSTING SHEET
A2: PRODUCT NAME:- | B2: ='BOM R2D CatWalk'!I119 -> WELDMENT,RAMPRAIL, PC4100 | D2: RFQ Ref.
A3: ITEM DRG NO | B3: ='BOM R2D CatWalk'!G119 -> AY30133 | D3: Total Quantity | E3: ='BOM R2D CatWalk'!K119 -> 1
A4: Total Net WT as per Drawing | B4: ='BOM R2D CatWalk'!N119 -> 113.7 | I4: Assy No | P4: ='RM Details'!H98 -> AY30133
A5: COSTBREAKUP OF COMPONENT (QTY-01 No.) | I5: S.No | J5: Type | K5: Size (mm) | L5: Material | M5: Sum of Total Weight (Kg) | N5: Sum of Gross Wt (kg) | O5: MOQ Weight | P5: Remarks | Q5: Cal. Weight | R5: Rate/Kg | S5: Cost
A6: RAW MATERIAL COST | I6: 1 | J6: Sq. Tube | K6: 50x50x 5thk | L6: YST 310 | M6: ='RM Details'!E100 -> 124.5734 | N6: ='RM Details'!F100 -> 137.03074 | O6: =6.56*6 -> 39.36 | Q6: =IF(O6>N6,O6,IF(O6<N6,N6)) -> 137.03074 | R6: 110 | S6: =R6*Q6 -> 15073.381
A7: SPEC | E7: YST 310 | K7: Total | M7: =SUM(M6:M6) -> 124.5734 | N7: =SUM(N6:N6) -> 137.03074 | Q7: =SUM(Q6:Q6) -> 137.03074 | R7: =S7/Q7 -> 110 | S7: =SUM(S6:S6) -> 15073.381
A8: GROSS WT. (KG) | E8: =Q6 -> 137.03074 | F8: =SUM(C8:E8) -> 137.03074
A9: NET WT (KG) | E9: =M6 -> 124.5734 | F9: =SUM(C9:E9) -> 124.5734
A10: SCRAP (KG) | E10: =(E8-E9)*80% -> 9.965872 | F10: =(F8-F9)/F9 -> 0.1
A11: RM RATE (RS/KG) | E11: 200 | F11: =SUMPRODUCT(B11:E11,B8:E8) -> 27406.148
A12: SCRAP RATE (RS/KG) | E12: 30
A13: NET RM COST (RS) | D13: =(D8*D11)-(D10*D12) -> 0 | E13: =(E8*E11)-(E10*E12) -> 27107.172 | F13: =SUM(B13:E13) -> 27107.172
A14: TOTAL (RS) | B14: =SUM(B13:E13) -> 27107.172 | F14: =F13/F8 -> 197.81818
A15: BOP COST
A16: BOP COST (RS)
A17: TOTAL BOP | E17: =SUM(E16:E16) -> 0
A18: TOTAL OF RM + BOP (RS) | E18: =B14+E17 -> 27107.172
A19: PROCESS COST
A20: SPEC | B20: QTY | C20: RATE | E20: TOTAL COST
A21: LASER /PLASMA/PIPE - Cutting (Min.) | B21: ='BOM R2D CatWalk'!X119 -> 54 | C21: 35 | E21: =B21*C21 -> 1890 | G21: =E21/$F$9 -> 15.171778
A22: Machining (Hrs) | B22: ='BOM R2D CatWalk'!AB119/60 -> 0.23333333 | C22: 1000 | E22: =B22*C22 -> 233.33333 | G22: =E22/$F$9 -> 1.873059
A23: BENDING BY CNC BENDING (STROKE) | B23: ='BOM R2D CatWalk'!Z119 -> 0 | C23: 100 | E23: =B23*C23 -> 0 | G23: =E23/$F$9 -> 0
A24: MIG WELDING (MTR.) | B24: ='BOM R2D CatWalk'!AF119 -> 6 | C24: 250 | E24: =B24*C24 -> 1500 | G24: =E24/$F$9 -> 12.041094
A25: GRINDING/BUFFING & FINISHING (hrs) | B25: =B24/12 -> 0.5 | C25: 250 | E25: =B25*C25 -> 125 | G25: =E25/$F$9 -> 1.0034245
A26: INSPECTION & TESTING (HRS) | B26: =F9/95 -> 1.3112989 | C26: 1200 | E26: =B26*C26 -> 1573.5587 | G26: =E26/$F$9 -> 12.631579
A27: STRESS RELIEVING | C27: 250 | E27: =B27*C27 -> 0 | F27: As Actual, If required | G27: =E27/$F$9 -> 0
A28: Shot Blasting | C28: 5 | E28: =C28*F9 -> 622.867 | G28: =E28/$F$9 -> 5
A29: Hot Dip Galvanization | B29: 0 | C29: 50 | E29: =B29*C29 -> 0 | G29: =E29/$F$9 -> 0
A30: PAINTING (including material & Labor) | B30: ='BOM R2D CatWalk'!AI119 -> 4.153915 | C30: 1250 | E30: =B30*C30 -> 5192.3937 | F30: No paint Detail Found | G30: =E30/$F$9 -> 41.6814
A31: Stamping Cost (HRS)/Straightning | B31: 4 | C31: 250 | E31: =B31*C31 -> 1000 | G31: =E31/$F$9 -> 8.0273959
A32: FE cost | C32: 4.5 | E32: =C32*F9 -> 560.5803 | G32: =E32/$F$9 -> 4.5
A33: TOTAL PROCESS COST OF PC | E33: =SUM(E21:E32) -> 12697.733 | G33: =E33/$F$9 -> 101.92973
A34: TOTAL RM+BOP+PC | E34: =E18+E33 -> 39804.905
A35: OH + Contingency | D35: 0.1 | E35: =E34*D35 -> 3980.4905 | G35: =E35/$F$9 -> 31.952973
A36: Total Product Cost Without Profit | E36: =SUM(E34:E35) -> 43785.395 | G36: =E36/F9 -> 351.4827 | H36: =E36/F8 -> 319.52973
F39: Min.
A40: NOTES:- Joint need to make while welding | E40: OTHER COST | F40: Min.
A41: No BOP found in the Drawing Details
A42: Stress relieveing NOT FOUND ON PRINTS, IF REQUIRED | E42: As Actual
...

Sheet Item-7_AT30107
A1: COSTING SHEET
A2: PRODUCT NAME:- | B2: ='BOM R2D CatWalk'!I114 -> WELDMENT,SKATE BODY, REVERSE VEE, PC4100 | D2: RFQ Ref.
A3: ITEM DRG NO | B3: ='BOM R2D CatWalk'!G114 -> AY30107 | D3: Total Quantity | E3: ='BOM R2D CatWalk'!K114 -> 1
A4: Total Net WT as per Drawing | B4: ='BOM R2D CatWalk'!N114 -> 80 | I4: Assy No | P4: ='RM Details'!H87 -> AY30107
A5: COSTBREAKUP OF COMPONENT (QTY-01 No.) | I5: S.No | J5: Type | K5: Size (mm) | L5: Material | M5: Sum of Total Weight (Kg) | N5: Sum of Gross Wt (kg) | O5: MOQ Weight | P5: Remarks | Q5: Cal. Weight | R5: Rate/Kg | S5: Cost
A6: RAW MATERIAL COST | I6: 1 | J6: Plate | K6: 10 | L6: E350 A/BR | M6: ='RM Details'!E89 -> 2 | N6: ='RM Details'!F89 -> 4.1130232 | Q6: =IF(O6>N6,O6,IF(O6<N6,N6)) -> 4.1130232 | R6: 90 | S6: =R6*Q6 -> 370.17209
