Workbook
Name a: #REF!
Name a: #REF!
Name a: '[1]BOM '!#REF!
Name a: #REF!
Name a_1: #REF!
Name a_1: #REF!
Name a_1: #REF!
Name b: #REF!
Name b: #REF!
Name b: #REF!

Sheet Customer Data 
A1: Part ID | B1: Description | C1: Usage
A2: AY30013 | B2: WELDMENT, PC4100 R2D SLAVE SKID, PC4100 | C2: 1
A3: AY30017 | B3: WELDMENT, FALSE FLOOR, PC4100 | C3: 2
A4: AY30018 | B4: WELDMENT, HINGED FLOOR, PC4100 | C4: 1
A5: AY30027 | B5: WELDMENT, HINGED FLOOR, PC4100 | C5: 23
A6: AY30062 | B6: WELDMENT, SAFETY BAR, PC4100 | C6: 1
A7: AY30084 | B7: HAND RAIL, WELDMENT, 42" CATWALK, PC4100 | C7: 4
A8: AY30107 | B8: WELDMENT,SKATE BODY, REVERSE VEE,PC4100 | C8: 1
A9: AY30130 | B9: WELDMENT, PC4100, 42' CATWALK, RAMP B | C9: 0
A10: AY30133 | B10: WELDMENT, RAMP RAIL, PC4100 | C10: 1
A11: AY30134 | B11: WLDMNT, RAMP, SHEAVE SUB B, PC4100 | C11: 1
A12: AY30144 | B12: WELDMENT, 30FT LIFT ARM, PC4100 | C12: 1
A13: AY30150 | B13: WELDMENT, SPEAR FRAME, PC4100 | C13: 1
... A16: AY51606 | B16: KIT, SHIPPING BRKTS, LONG,PC4000 | C16: 1

Sheet Quote Buggy Parts 
A1: RECURRING COST | D1: ITEM-1
D2: Assy. No | E2: Qty.
D3: ='BOM RAMPRAIL_AY30133'!F3 -> AY30133 | E3: 5
A4: A. | B4: RM Cost | D4: Weight in Kg. | E4: Price in INR
A5: i. | B5: RM Gross Weight | D5: =Summary!G8 -> 228.15242
A6: ii. | B6: RM Net Weight | D6: =Summary!G9 -> 167.21302
A7: iii. | B7: Raw Material Cost | E7: =Summary!G13 -> 18585.923
A8: iv. | B8: Fastener and BOP | C8: No detail in Drg. | E8: 0
B9: TOTAL RM COST | E9: =SUM(E7:E8) -> 18585.923
D10: =(D5-D6)/D6 -> 0.36444171
A11: B. | B11: Process Cost
A12: i. | B12: Assy Cost | C12: 0 | E12: 0
A13: ii. | B13: Fabrication / Process Cost | C13: 0 | E13: =Summary!F33 -> 3873.1881
A14: iii. | B14: Paint | C14: 0 | E14: =D6*20 -> 3344.2604
A15: iv. | B15: Inspection and Testing | C15: 0 | E15: =D6*12 -> 2006.5562
A16: v. | B16: Packaging | C16: Canrig Scope | E16: 0
B17: TOTAL BASIC COST | E17: =SUM(E9:E16) -> 27809.928
A19: C. | B19: Fixed Cost
A20: i | B20: ICC Cost | C20: 0.015 | E20: =E22*$C$20 -> 627.63895
A21: ii | B21: Rejection | C21: 0.015 | E21: =E22*$C$21 -> 627.63895
B22: Sub Total | E22: =SUM(E20:E21)+E17 -> 41842.596
A24: D. | B24: Variable Cost
A25: i. | B25: Contingency / Warranty | C25: 0.02 | E25: =E28*$C$25 -> 1101.121
A26: ii. | B26: Overheads | C26: 0.1 | E26: =E28*$C$26 -> 5505.6048
A27: iii. | B27: Contribution / Profit | C27: 0.12 | E27: =E28*$C$27 -> 6606.7258
B28: Total Price | E28: =SUM(E22:E27) -> 55056.048
A30: F | B30: Transportation | C30: EX Works | E30: 0
B31: Total Price for X Parts | D31: =E3 -> 5 | E31: =SUM(E28:E30) -> 55056.048
B32: Total Cost Each Part | E32: =E31/E3 -> 11011.21
B34: Rate Per Gross Wt kg | E34: =E31/D5 -> 241.31258
B35: Rate Per Net Wt kg | E35: =E31/D6 -> 329.25695
B36: Internal Cal. Cost Per X parts | D36: =E3 -> 5 | E36: =Summary!F36 -> 24705.022
B37: Margin | E37: =E31-E36 -> 16295.896
B38: Margin % | E38: =(E31-E36)/E31 -> 0.29598739
A44: NON-RECURRING COST | D44: ITEM-1
A45: 1 | B45: ENGINEERING CHARGES | E45: =Summary!D51 -> 5000
A46: 2 | B46: DEVELOPMENT OF JIG AND FIXTURES (01 time) | E46: =Summary!D50+Summary!D52 -> 23961.295
B47: Sub Total | E47: =SUM(E45:E46) -> 28961.295
B48: Overheads | C48: 0.1 | E48: =E50*$C$48 -> 3712.9865
B49: Contribution / Profit | C49: 0.12 | E49: =E50*$C$49 -> 4455.5838
...

Sheet Summary
A1: COSTING SHEET
A2: PRODUCT NAME:- | B2: ='BOM RAMPRAIL_AY30133'!H3 -> WELDMENT,RAMPRAIL, PC4100 | E2: RFQ Ref.
A3: ITEM DRG NO | B3: ='BOM RAMPRAIL_AY30133'!F3 -> AY30133 | E3: Total Quantity | F3: ='BOM RAMPRAIL_AY30133'!J3 -> 1
A4: Total Net WT as per Drawing | C4: ='BOM RAMPRAIL_AY30133'!M3 -> 113.7 | I4: RM Details Assy. No
A5: COSTBREAKUP OF COMPONENT (QTY-01 No.) | I5: Type | J5: Drg. Material | K5: Material | L5: Size (thk) | M5: Net Wet(kg) | N5: Gross Weight (kg)
A6: RAW MATERIAL COST | I6: Plate | J6: ASTM A36/ Q235 | K6: IS 2062 E250 A/BO/BR | L6: 8 | M6: ='RM Details'!E4 -> 158.59462 | N6: ='RM Details'!F4 -> 218.0676
A7: SPEC | D7: IS 2062 E250 A/BO/BR | F7: ASTM A514 | I7: Plate | J7: ASTM A514/Q690 | K7: ASTM A514 | L7: 20 | M7: ='RM Details'!E5 -> 8.6184 | N7: ='RM Details'!F5 -> 10.084816
A8: GROSS WT. (KG) | D8: =N6 -> 218.0676 | F8: =N7 -> 10.084816 | G8: =SUM(B8:F8) -> 228.15242
A9: NET WT (KG) | D9: =M6 -> 158.59462 | F9: =M7 -> 8.6184 | G9: =SUM(B9:F9) -> 167.21302
A10: SCRAP (KG) | D10: =(D8-D9)*80% -> 47.578385 | F10: =(F8-F9)*80% -> 1.1731332 | G10: =(G8-G9)/G9 -> 0.36444171
A11: RM RATE (RS/KG) | D11: 85 | F11: 150 | G11: =SUMPRODUCT(B11:F11,B8:F8) -> 20048.468
A12: SCRAP RATE (RS/KG) | D12: 30 | F12: 30
A13: NET RM COST (RS) | D13: =(D8*D11)-(D10*D12) -> 17108.394 | F13: =(F8*F11)-(F10*F12) -> 1477.5285 | G13: =SUM(B13:F13) -> 18585.923
A14: TOTAL (RS) | B14: =SUM(B13:F13) -> 18585.923 | G14: =G13/G8 -> 81.462748
A15: BOP COST
A16: BOP COST (RS)
A17: TOTAL BOP | F17: =SUM(F16:F16) -> 0
A18: TOTAL OF RM + BOP (RS) | F18: =B14+F17 -> 18585.923
A19: PROCESS COST
A20: SPEC | B20: QTY | D20: RATE | F20: TOTAL COST
A21: LASER /PLASMA/PIPE - Cutting (Min.) | B21: ='BOM RAMPRAIL_AY30133'!W3 -> 0 | D21: 50 | E21: Laser part | F21: =B21*D21 -> 0 | H21: =F21/$G$9 -> 0
A22: Machining (Hrs) | B22: ='BOM RAMPRAIL_AY30133'!AA3/60 -> 0.2 | D22: 550 | F22: =B22*D22 -> 110 | H22: =F22/$G$9 -> 0.65784352
A23: BENDING BY CNC BENDING (STROKE) | B23: ='BOM RAMPRAIL_AY30133'!Y3 -> 0 | D23: 10 | F23: =B23*D23 -> 0 | H23: =F23/$G$9 -> 0
A24: MIG WELDING (MTR.) | B24: ='BOM RAMPRAIL_AY30133'!AE3 -> 0 | D24: 250 | F24: =B24*D24 -> 0 | H24: =F24/$G$9 -> 0
A25: GRINDING/BUFFING & FINISHING (hrs) | B25: =B24/15 -> 0 | D25: 250 | F25: =B25*D25 -> 0 | H25: =F25/$G$9 -> 0
A26: INSPECTION & TESTING (HRS) | B26: =G9/95 -> 1.760137 | D26: 1200 | F26: =B26*D26 -> 2112.1644 | H26: =F26/$G$9 -> 12.631579
A27: STRESS RELIEVING | D27: 250 | F27: =B27*D27 -> 0 | G27: As Actual, If required | H27: =F27/$G$9 -> 0
A28: Shot Blasting | D28: 5 | F28: =D28*G9 -> 836.06509 | H28: =F28/$G$9 -> 5
A29: Hot Dip Galvanization | B29: 0 | D29: 50 | F29: =B29*D29 -> 0 | H29: =F29/$G$9 -> 0
A30: PAINTING (including material & Labor) | B30: ='BOM RAMPRAIL_AY30133'!AH3 -> 0 | D30: 1250 | F30: =B30*D30 -> 0 | G30: No paint Detail Found | H30: =F30/$G$9 -> 0
A31: Stamping Cost (HRS) | B31: =15/60 -> 0.25 | D31: 250 | F31: =B31*D31 -> 62.5 | H31: =F31/$G$9 -> 0.37377473
A32: FE cost | D32: 4.5 | F32: =D32*G9 -> 752.45858 | H32: =F32/$G$9 -> 4.5
A33: TOTAL PROCESS COST OF PC | F33: =SUM(F21:F32) -> 3873.1881 | H33: =F33/$G$9 -> 23.163197
A34: TOTAL RM+BOP+PC | F34: =F18+F33 -> 22459.111
A35: OH + Contingency | E35: 0.1 | F35: =F34*E35 -> 2245.9111 | H35: =F35/$G$9 -> 13.431437
A36: Total Product Cost Without Profit | F36: =SUM(F34:F35) -> 24705.022 | H36: =F36/G9 -> 147.74581 | I36: =F36/G8 -> 108.28297
G39: Min.
A40: NOTES:- | F40: OTHER COST | G40: Min.
A41: No BOP found in the Drawing Details
A42: Stress relieveing NOT FOUND ON PRINTS, IF REQUIRED | F42: As Actual
...

Sheet BOM RAMPRAIL_AY30133
A1: S.No | C1: Level | F1: BOM WELDMENT,RAMPRAIL, PC4100_AY30133 | L1: 0.4536 | R1: 25.4 | U1: 0.1 | V1: 0.15 | AB1: 550 | AE1: 0.2
B2: Assembly | C2: L1 | D2: L2 | E2: L3 | F2: Drawing No. | G2: Rev | H2: Description | I2: Qty. | J2: Total Qty. | K2: Net Wt. LBS | L2: Net Weight (Kg) | M2: Total Weight (Kg) | N2: Type | O2: DRG. Material | P2: Alt. Material | Q2: IS Thk (Inch) | R2: IS Thk (mm) | S2: Width | T2: Length | U2: Gross Wt (kg) | V2: Cutting Perimeter | W2: Cutting Time | X2: Cutting Cost | Y2: No. of bends | Z2: Bending Details | AA2: Machining Time (min) | AB2: Machining Cost | AC2: Other Process | AD2: Other process Cost | AE2: Welding Length (M) | AF2: Remarks | AG2: Paint | AH2: Surface Area SQM
A3: 1 | C3: 1 | F3: AY30133 | G3: A | H3: WELDMENT,RAMPRAIL, PC4100 | I3: ='Customer Data '!C8 -> 1 | J3: =I3 -> 1 | K3: 7057.6 | L3: 113.7 | M3: =L3*J3 -> 113.7 | N3: Main Assy. | U3: =SUM(U4:U10) -> 0 | W3: =SUMPRODUCT(W4:W10,$J$4:$J$10) -> 0 | X3: =SUM(X4:X10) -> 0 | Y3: =SUMPRODUCT(Y4:Y10,$J$4:$J$10) -> 0 | AA3: =SUMPRODUCT(AA4:AA10,$J$4:$J$10) -> 12 | AB3: =SUM(AB4:AB10) -> 110 | AC3: STAMP | AE3: ='Welding Details'!G3*(1+$AE$1)*J3/1000 -> 0 | AH3: =SUM(AH4:AH10) -> 0
A4: 2 | D4: 1.1 | H4: HSS 50x50x5x12187 LG | I4: 1 | J4: =I4*$J$3 -> 1 | L4: =7.07*T4/1000 -> 86.16209 | M4: =L4*J4 -> 86.16209 | N4: Sq. Tube | O4: ASTM A516 Gr. 70/S275JR | R4: 50x50x5 thk | T4: 12187 | AA4: 2 | AB4: =AA4*$AB$1/60*J4 -> 18.333333
A5: 3 | D5: 1.2 | H5: HSS 50x50x5x219 LG | I5: 2 | J5: =I5*$J$3 -> 2 | L5: =7.07*T5/1000 -> 1.54833 | M5: =L5*J5 -> 3.09666 | N5: Sq. Tube | O5: ASTM A516 Gr. 70/S275JR | R5: 50x50x5 thk | T5: 219 | AA5: 2 | AB5: =AA5*$AB$1/60*J5 -> 36.666667
A6: 4 | D6: 1.3 | H6: HSS 50x50x5x87 LG | I6: 2 | J6: =I6*$J$3 -> 2 | L6: =7.07*T6/1000 -> 0.61509 | M6: =L6*J6 -> 1.23018 | N6: Sq. Tube | O6: ASTM A516 Gr. 70/S275JR | R6: 50x50x5 thk | T6: 87 | AA6: 2 | AB6: =AA6*$AB$1/60*J6 -> 36.666667
A7: 5 | D7: 1.4 | H7: HSS 50x50x5x191 LG | I7: 17 | J7: =I7*$J$3 -> 17 | L7: =7.07*T7/1000 -> 1.35037 | M7: =L7*J7 -> 22.95629 | N7: Sq. Tube | O7: ASTM A516 Gr. 70/S275JR | R7: 50x50x5 thk | T7: 191
A8: 6 | D8: 1.5 | H8: HSS 50x50x5x397 LG | I8: 2 | J8: =I8*$J$3 -> 2 | L8: =7.07*T8/1000 -> 2.80679 | M8: =L8*J8 -> 5.61358 | N8: Sq. Tube | O8: ASTM A516 Gr. 70/S275JR | R8: 50x50x5 thk | T8: 397
A9: 7 | D9: 1.6 | H9: HSS 50x50x5x410 LG | I9: 1 | J9: =I9*$J$3 -> 1 | L9: =7.07*T9/1000 -> 2.8987 | M9: =L9*J9 -> 2.8987 | N9: Sq. Tube | O9: ASTM A516 Gr. 70/S275JR | R9: 50x50x5 thk | T9: 410 | AA9: 2 | AB9: =AA9*$AB$1/60*J9 -> 18.333333
A10: 8 | D10: 1.7 | H10: HSS 50x50x5x51 LG | I10: 1 | J10: =I10*$J$3 -> 1 | L10: =7.07*T10/1000 -> 0.36057 | M10: =L10*J10 -> 0.36057 | N10: Sq. Tube | O10: ASTM A516 Gr. 70/S275JR | R10: 50x50x5 thk | T10: 51
A11: 9 | D11: 1.8 | H11: HSS 50x50x5x319 LG | I11: 1 | J11: =I11*$J$3 -> 1 | L11: =7.07*T11/1000 -> 2.25533 | M11: =L11*J11 -> 2.25533 | N11: Sq. Tube | O11: ASTM A516 Gr. 70/S275JR | R11: 50x50x5 thk | T11: 319 | AA11: 2 | AB11: =AA11*$AB$1/60*J11 -> 18.333333

Sheet RM Details
H1: Assembly | I1: DT34962
A2: RM Details Assy. No | E2: =I1 -> DT34962
A3: Type | B3: Drg. Material | C3: Material | D3: Size (thk) | E3: Net Wet(kg) | F3: Gross Weight (kg) | I3: Column Labels
A4: Plate | B4: ASTM A36/ Q235 | C4: IS 2062 E250 A/BO/BR | D4: 8 | E4: =GETPIVOTDATA("Sum of Total Weight (Kg)",$H$3,"Alt. Material","IS 2062 E250 A/BO/BR","IS Thk (mm)",8) -> 158.59462 | F4: =GETPIVOTDATA("Sum of Gross Wt (kg)",$H$3,"Alt. Material","IS 2062 E250 A/BO/BR","IS Thk (mm)",8) -> 218.0676 | I4: ASTM A514 | K4: IS 2062 E250 A/BO/BR | M4: Total Sum of Total Weight (Kg) | N4: Total Sum of Gross Wt (kg)
A5: Plate | B5: ASTM A514/Q690 | C5: ASTM A514 | D5: 20 | E5: =GETPIVOTDATA("Sum of Total Weight (Kg)",$H$3,"Alt. Material","ASTM A514","IS Thk (mm)",20) -> 8.6184 | F5: =GETPIVOTDATA("Sum of Gross Wt (kg)",$H$3,"Alt. Material","ASTM A514","IS Thk (mm)",20) -> 10.084816 | H5: Row Labels | I5: Sum of Total Weight (Kg) | J5: Sum of Gross Wt (kg) | K5: Sum of Total Weight (Kg) | L5: Sum of Gross Wt (kg)
H6: 8 | K6: 158.59462 | L6: 218.0676 | M6: 158.59462 | N6: 218.0676
H7: 20 | I7: 8.6184 | J7: 10.084816 | M7: 8.6184 | N7: 10.084816
H8: Grand Total | I8: 8.6184 | J8: 10.084816 | K8: 158.59462 | L8: 218.0676 | M8: 167.21302 | N8: 228.15242
A11: RM Details Assy. No | E11: =I11 -> DT34961 | H11: Assembly | I11: DT34961
A12: Type | B12: Drg. Material | C12: Material | D12: Size (thk) | E12: Net Wet(kg) | F12: Gross Weight (kg)
A13: Plate | B13: ASTM A36/ Q235 | C13: IS 2062 E250 A/BO/BR | D13: 8 | E13: =GETPIVOTDATA("Sum of Total Weight (Kg)",$H$13,"IS Thk (mm)",8) -> 177.39731 | F13: =GETPIVOTDATA("Sum of Gross Wt (kg)",$H$13,"IS Thk (mm)",8) -> 243.92131 | I13: Column Labels
A14: Plate | B14: ASTM A514/Q690 | C14: ASTM A514 | D14: 20 | E14: =GETPIVOTDATA("Sum of Total Weight (Kg)",$H$13,"Alt. Material","ASTM A514","IS Thk (mm)",20) -> 8.6184 | F14: =GETPIVOTDATA("Sum of Gross Wt (kg)",$H$13,"Alt. Material","ASTM A514","IS Thk (mm)",20) -> 10.084816 | I14: ASTM A514 | K14: IS 2062 E250 A/BO/BR | M14: Total Sum of Total Weight (Kg) | N14: Total Sum of Gross Wt (kg)
H15: Row Labels | I15: Sum of Total Weight (Kg) | J15: Sum of Gross Wt (kg) | K15: Sum of Total Weight (Kg) | L15: Sum of Gross Wt (kg)
H16: 8 | K16: 177.39731 | L16: 243.92131 | M16: 177.39731 | N16: 243.92131
H17: 20 | I17: 8.6184 | J17: 10.084816 | M17: 8.6184 | N17: 10.084816
H18: Grand Total | I18: 8.6184 | J18: 10.084816 | K18: 177.39731 | L18: 243.92131 | M18: 186.01571 | N18: 254.00612
A21: RM Details Assy. No | E21: =I21 -> DT14062 | H21: Assembly | I21: DT14062
A22: Type | B22: Drg. Material | C22: Material | D22: Size (thk) | E22: Net Wet(kg) | F22: Gross Weight (kg)
A23: Plate | B23: ASTM A36/ Q235 | C23: IS 2062 E250 A/BO/BR | D23: 6 | E23: =GETPIVOTDATA("Sum of Total Weight (Kg)",$H$23,"Alt. Material","IS 2062 E250 A/BO/BR","IS Thk (mm)",6) -> 1.0099502 | F23: =GETPIVOTDATA("Sum of Gross Wt (kg)",$H$23,"Alt. Material","IS 2062 E250 A/BO/BR","IS Thk (mm)",6) -> 1.5870646 | I23: Column Labels
A24: Plate | B24: ASTM A36/ Q235 | C24: IS 2062 E250 A/BO/BR | D24: 20 | E24: =GETPIVOTDATA("Sum of Total Weight (Kg)",$H$23,"Alt. Material","IS 2062 E250 A/BO/BR","IS Thk (mm)",20) -> 179.33084 | F24: =GETPIVOTDATA("Sum of Gross Wt (kg)",$H$23,"Alt. Material","IS 2062 E250 A/BO/BR","IS Thk (mm)",20) -> 253.90306 | I24: 42CrMo4 / EN 19 | K24: IS 2062 E250 A/BO/BR | M24: Total Sum of Total Weight (Kg) | N24: Total Sum of Gross Wt (kg)
A25: Rod | B25: AISI 4140 HTSR | C25: 42CrMo4 / EN 19 | D25: Dia 65 | E25: =GETPIVOTDATA("Sum of Total Weight (Kg)",$H$23,"Alt. Material","42CrMo4 / EN 19","IS Thk (mm)","Dia 65") -> 68.04 | F25: =GETPIVOTDATA("Sum of Gross Wt (kg)",$H$23,"Alt. Material","42CrMo4 / EN 19","IS Thk (mm)","Dia 65") -> 97.405 | H25: Row Labels | I25: Sum of Total Weight (Kg) | J25: Sum of Gross Wt (kg) | K25: Sum of Total Weight (Kg) | L25: Sum of Gross Wt (kg)
H26: 6 | K26: 1.0099502 | L26: 1.5870646 | M26: 1.0099502 | N26: 1.5870646
H27: 20 | K27: 179.33084 | L27: 253.90306 | M27: 179.33084 | N27: 253.90306
H28: Dia 65 | I28: 68.04 | J28: 97.405 | M28: 68.04 | N28: 97.405
H29: Grand Total | I29: 68.04 | J29: 97.405 | K29: 180.34079 | L29: 255.49012 | M29: 248.38079 | N29: 352.89512
A33: RM Details Assy. No | E33: =I33 -> DT14077 | H33: Assembly | I33: DT14077
A34: Type | B34: Drg. Material | C34: Material | D34: Size (thk) | E34: Net Wet(kg) | F34: Gross Weight (kg)
A35: Plate | B35: ASTM A36/ Q235 | C35: IS 2062 E250 A/BO/BR | D35: 6 | E35: =GETPIVOTDATA("Sum of Total Weight (Kg)",$H$35,"Alt. Material","IS 2062 E250 A/BO/BR","IS Thk (mm)",6) -> 0.45775031 | F35: =GETPIVOTDATA("Sum of Gross Wt (kg)",$H$35,"Alt. Material","IS 2062 E250 A/BO/BR","IS Thk (mm)",6) -> 0.71932192 | I35: Column Labels
A36: Plate | B36: ASTM A36/ Q235 | C36: IS 2062 E250 A/BO/BR | D36: 20 | E36: =GETPIVOTDATA("Sum of Total Weight (Kg)",$H$35,"Alt. Material","IS 2062 E250 A/BO/BR","IS Thk (mm)",20) -> 73.946179 | F36: =GETPIVOTDATA("Sum of Gross Wt (kg)",$H$35,"Alt. Material","IS 2062 E250 A/BO/BR","IS Thk (mm)",20) -> 104.51115 | I36: 42CrMo4 / EN 19 | K36: IS 2062 E250 A/BO/BR | M36: Total Sum of Total Weight (Kg) | N36: Total Sum of Gross Wt (kg)
A37: Rod | B37: AISI 4140 HTSR | C37: 42CrMo4 / EN 19 | D37: Dia 65 | E37: =GETPIVOTDATA("Sum of Total Weight (Kg)",$H$35,"Alt. Material","42CrMo4 / EN 19","IS Thk (mm)","Dia 65") -> 30.02832 | F37: =GETPIVOTDATA("Sum of Gross Wt (kg)",$H$35,"Alt. Material","42CrMo4 / EN 19","IS Thk (mm)","Dia 65") -> 41.888 | H37: Row Labels | I37: Sum of Total Weight (Kg) | J37: Sum of Gross Wt (kg) | K37: Sum of Total Weight (Kg) | L37: Sum of Gross Wt (kg)
H38: 6 | K38: 0.45775031 | L38: 0.71932192 | M38: 0.45775031 | N38: 0.71932192
H39: 20 | K39: 73.946179 | L39: 104.51115 | M39: 73.946179 | N39: 104.51115
H40: Dia 65 | I40: 30.02832 | J40: 41.888 | M40: 30.02832 | N40: 41.888
H41: Grand Total | I41: 30.02832 | J41: 41.888 | K41: 74.403929 | L41: 105.23047 | M41: 104.43225 | N41: 147.11847
A44: RM Details Assy. No | E44: =I44 -> DT14647 | H44: Assembly | I44: DT14647
A45: Type | B45: Drg. Material | C45: Material | D45: Size (thk) | E45: Net Wet(kg) | F45: Gross Weight (kg)
A46: Plate | B46: ASTM A514 GR B | C46: ASTM A514 GR B | D46: 25 | E46: =GETPIVOTDATA("Sum of Total Weight (Kg)",$H$46,"Alt. Material","ASTM A514 GR B","IS Thk (mm)",25) -> 17.907126 | F46: =GETPIVOTDATA("Sum of Gross Wt (kg)",$H$46,"Alt. Material","ASTM A514 GR B","IS Thk (mm)",25) -> 26.07144 | I46: Column Labels
A47: Plate | B47: ASTM A514 GR B | C47: ASTM A514 GR B | D47: 32 | E47: =GETPIVOTDATA("Sum of Total Weight (Kg)",$H$46,"Alt. Material","ASTM A514 GR B","IS Thk (mm)",32) -> 105.19452 | F47: =GETPIVOTDATA("Sum of Gross Wt (kg)",$H$46,"Alt. Material","ASTM A514 GR B","IS Thk (mm)",32) -> 120.75737 | I47: 1.7218 (25CrMo4) | K47: ASTM A514 GR B | M47: Total Sum of Total Weight (Kg) | N47: Total Sum of Gross Wt (kg)
A48: Plate | B48: AISI 4130 | C48: 1.7218 (25CrMo4) | D48: Dia 90 | E48: =GETPIVOTDATA("Sum of Total Weight (Kg)",$H$46,"Alt. Material","1.7218 (25CrMo4)","IS Thk (mm)","Dia 90") -> 3.3 | F48: =GETPIVOTDATA("Sum of Gross Wt (kg)",$H$46,"Alt. Material","1.7218 (25CrMo4)","IS Thk (mm)","Dia 90") -> 4.015 | H48: Row Labels | I48: Sum of Total Weight (Kg) | J48: Sum of Gross Wt (kg) | K48: Sum of Total Weight (Kg) | L48: Sum of Gross Wt (kg)
H49: 25 | K49: 17.907126 | L49: 26.07144 | M49: 17.907126 | N49: 26.07144
...

Sheet Welding Details
B2: Assy No. | C2: Item No. | D2: Weld Length | E2: No of Run | F2: No of Places | G2: Total Weld

Sheet Paint Details
H2: Akzonobel
G3: Total Area | H3: ='BOM RAMPRAIL_AY30133'!AH3 -> 0 | I3: SQM | J3: As per drawing
C4: Paint Details | D4: DFT | E4: Th Coverage (Area m2) | F4: Wastage factor | G4: Actual Coverage (Area m2) | H4: Req Paint (Litre) | I4: Rate of paint | J4: Amount
B5: Primer | C5: Interzinc 42 | D5: 50-75 | E5: =75*7.33/75 -> 7.33 | F5: 0.35 | G5: =E5*(100%-F5) -> 4.7645 | H5: =(1/G5)*$H$3 -> 0 | I5: 1000 | J5: =H5*I5 -> 0 | K5: 1
B6: Paint | C6: Interthane 990 white | D6: 50-75 | E6: =50*11.4/50 -> 11.4 | F6: 0.35 | G6: =E6*(100%-F6) -> 7.41 | H6: =(1/G6)*$H$3 -> 0 | I6: 1000 | J6: =H6*I6 -> 0 | K6: 1
B7: Thinner | H7: =SUM(H5:H6)*0.3 -> 0 | I7: 400 | J7: =H7*I7 -> 0
B8: Total | H8: =SUM(H5:H7) -> 0 | J8: =SUM(J5:J7) -> 0
G9: Paint Applying Cost (Labour and Consuables) | J9: =H3*250 -> 0 | K9: `@250/SQM
B10: Total Paint Cost | J10: =J8+J9 -> 0
B11: Extra paint touch up cost (5%) | I11: 0.05 | J11: =J10*I11 -> 0
B12: Total cost | J12: =J11+J10 -> 0 | K12: =J12/H3 -> #DIV/0!
H17: Akzonobel
G18: Total Area | H18: =H3 -> 0 | J18: SQM | K18: As per drawing
C19: Paint Details | D19: DFT | E19: Th Coverage (Area m2) | F19: Wastage factor | G19: Actual Coverage (Area m2) | H19: Req Paint (Litre) | I19: Minimum Qty | J19: Rate of paint | K19: Amount
B20: Primer | C20: Interzinc 42 | D20: 75 | E20: =75*7.33/D20 -> 7.33 | F20: 0.35 | G20: =E20*(100%-F20) -> 4.7645 | H20: =(1/G20)*$H$3 -> 0 | I20: =H20 -> 0 | J20: 787.5 | K20: =J20*I20 -> 0 | L20: 1
B21: Paint | C21: Interthane 990 white | D21: 75 | E21: =50*13.6/D21 -> 9.0666667 | F21: 0.35 | G21: =E21*(100%-F21) -> 5.8933333 | H21: =(1/G21)*$H$3 -> 0 | I21: 20 | J21: 1200 | K21: =J21*I21 -> 24000 | L21: 1
B22: Thinner | H22: =SUM(H20:H21)*0.3 -> 0 | I22: =H22 -> 0 | J22: 200 | K22: =J22*I22 -> 0
B23: Total | H23: =SUM(H20:H22) -> 0 | K23: =SUM(K20:K22) -> 24000
G24: Paint Applying Cost (Labour and Consuables) | K24: =H18*250 -> 0 | L24: `@250/SQM
B25: Total Paint Cost | K25: =K23+K24 -> 24000
B26: Extra paint touch up cost (5%) | J26: 0.05 | K26: =K25*J26 -> 1200
B27: Total cost | K27: =K26+K25 -> 25200 | L27: =K27/H18 -> #DIV/0!
