Workbook
Name a: #REF!
Name a: #REF!
Name a: '[1]BOM '!#REF!
Name a: #REF!
Name a_1: #REF!
Name a_1: #REF!
Name a_1: #REF!
Name b: #REF!
Name b: #REF!
Name b: #REF!

Sheet Customer Data 
A1: Part ID | B1: Description | C1: Usage
A2: AY30013 | B2: WELDMENT, PC4100 R2D SLAVE SKID, PC4100 | C2: 1
A3: AY30017 | B3: WELDMENT, FALSE FLOOR, PC4100 | C3: 2
A4: AY30018 | B4: WELDMENT, HINGED FLOOR, PC4100 | C4: 1
A5: AY30027 | B5: WELDMENT, HINGED FLOOR, PC4100 | C5: 23
A6: AY30062 | B6: WELDMENT, SAFETY BAR, PC4100 | C6: 1
A7: AY30084 | B7: HAND RAIL, WELDMENT, 42" CATWALK, PC4100 | C7: 4
A8: AY30107 | B8: WELDMENT,SKATE BODY, REVERSE VEE,PC4100 | C8: 1
A9: AY30130 | B9: WELDMENT, PC4100, 42' CATWALK, RAMP B | C9: 0
A10: AY30133 | B10: WELDMENT, RAMP RAIL, PC4100 | C10: 1
A11: AY30134 | B11: WLDMNT, RAMP, SHEAVE SUB B, PC4100 | C11: 1
A12: AY30144 | B12: WELDMENT, 30FT LIFT ARM, PC4100 | C12: 1
A13: AY30150 | B13: WELDMENT, SPEAR FRAME, PC4100 | C13: 1
... A16: AY51606 | B16: KIT, SHIPPING BRKTS, LONG,PC4000 | C16: 1

Sheet Quote Buggy Parts 
A1: RECURRING COST | D1: ITEM-1
D2: Assy. No | E2: Qty.
D3: ='BOM R2D CatWalk'!F3 -> AY30011 | E3: 5
A4: A. | B4: RM Cost | D4: Weight in Kg. | E4: Price in INR
A5: i. | B5: RM Gross Weight | D5: =Summary!G8 -> 228.15242
A6: ii. | B6: RM Net Weight | D6: =Summary!G9 -> 167.21302
A7: iii. | B7: Raw Material Cost | E7: =Summary!G13 -> 18585.923
A8: iv. | B8: Fastener and BOP | C8: No detail in Drg. | E8: 0
B9: TOTAL RM COST | E9: =SUM(E7:E8) -> 18585.923
D10: =(D5-D6)/D6 -> 0.36444171
A11: B. | B11: Process Cost
A12: i. | B12: Assy Cost | C12: 0 | E12: 0
A13: ii. | B13: Fabrication / Process Cost | C13: 0 | E13: =Summary!F33 -> 5596.5214
A14: iii. | B14: Paint | C14: 0 | E14: =D6*20 -> 3344.2604
A15: iv. | B15: Inspection and Testing | C15: 0 | E15: =D6*12 -> 2006.5562
A16: v. | B16: Packaging | C16: Canrig Scope | E16: 0
B17: TOTAL BASIC COST | E17: =SUM(E9:E16) -> 29533.261
A19: C. | B19: Fixed Cost
A20: i | B20: ICC Cost | C20: 0.015 | E20: =E22*$C$20 -> 627.63895
A21: ii | B21: Rejection | C21: 0.015 | E21: =E22*$C$21 -> 627.63895
B22: Sub Total | E22: =SUM(E20:E21)+E17 -> 41842.596
A24: D. | B24: Variable Cost
A25: i. | B25: Contingency / Warranty | C25: 0.02 | E25: =E28*$C$25 -> 1101.121
A26: ii. | B26: Overheads | C26: 0.1 | E26: =E28*$C$26 -> 5505.6048
A27: iii. | B27: Contribution / Profit | C27: 0.12 | E27: =E28*$C$27 -> 6606.7258
B28: Total Price | E28: =SUM(E22:E27) -> 55056.048
A30: F | B30: Transportation | C30: EX Works | E30: 0
B31: Total Price for X Parts | D31: =E3 -> 5 | E31: =SUM(E28:E30) -> 55056.048
B32: Total Cost Each Part | E32: =E31/E3 -> 11011.21
B34: Rate Per Gross Wt kg | E34: =E31/D5 -> 241.31258
B35: Rate Per Net Wt kg | E35: =E31/D6 -> 329.25695
B36: Internal Cal. Cost Per X parts | D36: =E3 -> 5 | E36: =Summary!F36 -> 26600.689
B37: Margin | E37: =E31-E36 -> 16295.896
B38: Margin % | E38: =(E31-E36)/E31 -> 0.29598739
A44: NON-RECURRING COST | D44: ITEM-1
A45: 1 | B45: ENGINEERING CHARGES | E45: =Summary!D51 -> 5000
A46: 2 | B46: DEVELOPMENT OF JIG AND FIXTURES (01 time) | E46: =Summary!D50+Summary!D52 -> 23961.295
B47: Sub Total | E47: =SUM(E45:E46) -> 28961.295
B48: Overheads | C48: 0.1 | E48: =E50*$C$48 -> 3712.9865
B49: Contribution / Profit | C49: 0.12 | E49: =E50*$C$49 -> 4455.5838
...

Sheet Summary
A1: COSTING SHEET
A2: PRODUCT NAME:- | B2: ='BOM R2D CatWalk'!H3 -> WELDMENT, R2D CATWALK, LEV 1, PC4100 | E2: RFQ Ref.
A3: ITEM DRG NO | B3: ='BOM R2D CatWalk'!F3 -> AY30011 | E3: Total Quantity | F3: ='BOM R2D CatWalk'!J3 -> 1
A4: Total Net WT as per Drawing | C4: ='BOM R2D CatWalk'!M3 -> 3208 | I4: RM Details Assy. No
A5: COSTBREAKUP OF COMPONENT (QTY-01 No.) | I5: Type | J5: Drg. Material | K5: Material | L5: Size (thk) | M5: Net Wet(kg) | N5: Gross Weight (kg)
A6: RAW MATERIAL COST | I6: Plate | J6: ASTM A36/ Q235 | K6: IS 2062 E250 A/BO/BR | L6: 8 | M6: ='RM Details'!E4 -> 158.59462 | N6: ='RM Details'!F4 -> 218.0676
A7: SPEC | D7: IS 2062 E250 A/BO/BR | F7: ASTM A514 | I7: Plate | J7: ASTM A514/Q690 | K7: ASTM A514 | L7: 20 | M7: ='RM Details'!E5 -> 8.6184 | N7: ='RM Details'!F5 -> 10.084816
A8: GROSS WT. (KG) | D8: =N6 -> 218.0676 | F8: =N7 -> 10.084816 | G8: =SUM(B8:F8) -> 228.15242
A9: NET WT (KG) | D9: =M6 -> 158.59462 | F9: =M7 -> 8.6184 | G9: =SUM(B9:F9) -> 167.21302
A10: SCRAP (KG) | D10: =(D8-D9)*80% -> 47.578385 | F10: =(F8-F9)*80% -> 1.1731332 | G10: =(G8-G9)/G9 -> 0.36444171
A11: RM RATE (RS/KG) | D11: 85 | F11: 150 | G11: =SUMPRODUCT(B11:F11,B8:F8) -> 20048.468
A12: SCRAP RATE (RS/KG) | D12: 30 | F12: 30
A13: NET RM COST (RS) | D13: =(D8*D11)-(D10*D12) -> 17108.394 | F13: =(F8*F11)-(F10*F12) -> 1477.5285 | G13: =SUM(B13:F13) -> 18585.923
A14: TOTAL (RS) | B14: =SUM(B13:F13) -> 18585.923 | G14: =G13/G8 -> 81.462748
A15: BOP COST
A16: BOP COST (RS)
A17: TOTAL BOP | F17: =SUM(F16:F16) -> 0
A18: TOTAL OF RM + BOP (RS) | F18: =B14+F17 -> 18585.923
A19: PROCESS COST
A20: SPEC | B20: QTY | D20: RATE | F20: TOTAL COST
A21: LASER /PLASMA/PIPE - Cutting (Min.) | B21: ='BOM R2D CatWalk'!W3 -> 0 | D21: 50 | E21: Laser part | F21: =B21*D21 -> 0 | H21: =F21/$G$9 -> 0
A22: Machining (Hrs) | B22: ='BOM R2D CatWalk'!AA3/60 -> 3.3333333 | D22: 550 | F22: =B22*D22 -> 1833.3333 | H22: =F22/$G$9 -> 10.964059
A23: BENDING BY CNC BENDING (STROKE) | B23: ='BOM R2D CatWalk'!Y3 -> 0 | D23: 10 | F23: =B23*D23 -> 0 | H23: =F23/$G$9 -> 0
A24: MIG WELDING (MTR.) | B24: ='BOM R2D CatWalk'!AE3 -> 0 | D24: 250 | F24: =B24*D24 -> 0 | H24: =F24/$G$9 -> 0
A25: GRINDING/BUFFING & FINISHING (hrs) | B25: =B24/15 -> 0 | D25: 250 | F25: =B25*D25 -> 0 | H25: =F25/$G$9 -> 0
A26: INSPECTION & TESTING (HRS) | B26: =G9/95 -> 1.760137 | D26: 1200 | F26: =B26*D26 -> 2112.1644 | H26: =F26/$G$9 -> 12.631579
A27: STRESS RELIEVING | D27: 250 | F27: =B27*D27 -> 0 | G27: As Actual, If required | H27: =F27/$G$9 -> 0
A28: Shot Blasting | D28: 5 | F28: =D28*G9 -> 836.06509 | H28: =F28/$G$9 -> 5
A29: Hot Dip Galvanization | B29: 0 | D29: 50 | F29: =B29*D29 -> 0 | H29: =F29/$G$9 -> 0
A30: PAINTING (including material & Labor) | B30: ='BOM R2D CatWalk'!AH3 -> 0 | D30: 1250 | F30: =B30*D30 -> 0 | G30: No paint Detail Found | H30: =F30/$G$9 -> 0
A31: Stamping Cost (HRS) | B31: =15/60 -> 0.25 | D31: 250 | F31: =B31*D31 -> 62.5 | H31: =F31/$G$9 -> 0.37377473
A32: FE cost | D32: 4.5 | F32: =D32*G9 -> 752.45858 | H32: =F32/$G$9 -> 4.5
A33: TOTAL PROCESS COST OF PC | F33: =SUM(F21:F32) -> 5596.5214 | H33: =F33/$G$9 -> 33.469412
A34: TOTAL RM+BOP+PC | F34: =F18+F33 -> 24182.444
A35: OH + Contingency | E35: 0.1 | F35: =F34*E35 -> 2418.2444 | H35: =F35/$G$9 -> 14.462058
A36: Total Product Cost Without Profit | F36: =SUM(F34:F35) -> 26600.689 | H36: =F36/G9 -> 159.08264 | I36: =F36/G8 -> 116.59175
G39: Min.
A40: NOTES:- | F40: OTHER COST | G40: Min.
A41: No BOP found in the Drawing Details
A42: Stress relieveing NOT FOUND ON PRINTS, IF REQUIRED | F42: As Actual
...

Sheet BOM R2D CatWalk
A1: S.No | C1: Level | F1: BOM R2D Catwalk AY30011 | L1: 0.4536 | R1: 25.4 | U1: 0.1 | V1: 0.15 | AB1: 550 | AE1: 0.2
B2: Assembly | C2: L1 | D2: L2 | E2: L3 | F2: Drawing No. | G2: Rev | H2: Description | I2: Qty. | J2: Total Qty. | K2: Net Wt. LBS | L2: Net Weight (Kg) | M2: Total Weight (Kg) | N2: Type | O2: DRG. Material | P2: Alt. Material | Q2: IS Thk (Inch) | R2: IS Thk (mm) | S2: Width | T2: Length | U2: Gross Wt (kg) | V2: Cutting Perimeter | W2: Cutting Time | X2: Cutting Cost | Y2: No. of bends | Z2: Bending Details | AA2: Machining Time (min) | AB2: Machining Cost | AC2: Other Process | AD2: Other process Cost | AE2: Welding Length (M) | AF2: Remarks | AG2: Paint | AH2: Surface Area SQM
A3: 1 | C3: 1 | F3: AY30011 | G3: A | H3: WELDMENT, R2D CATWALK, LEV 1, PC4100 | I3: 1 | J3: =I3 -> 1 | K3: 7057.6 | L3: 3208 | M3: =L3*J3 -> 3208 | N3: Main Assy. | U3: =SUM(U4:U31) -> 0 | W3: =SUMPRODUCT(W4:W31,$J$4:$J$31) -> 0 | X3: =SUM(X4:X31) -> 0 | Y3: =SUMPRODUCT(Y4:Y31,$J$4:$J$31) -> 0 | AA3: =SUMPRODUCT(AA4:AA31,$J$4:$J$31) -> 200 | AB3: =SUM(AB4:AB31) -> 0 | AE3: ='Welding Details'!G3*(1+$AE$1)*J3/1000 -> 0 | AH3: =SUM(AH4:AH31) -> 0
A4: 2 | D4: 1.1 | F4: AY30010 | G4: A | H4: WELDMENT, CATWALK ODS BEAM, R2D, PC4100 | I4: 1 | J4: =I4*$J$3 -> 1 | L4: 679 | M4: =L4*J4 -> 679 | N4: Sub Assy. | O4: SEE BOM
A5: 3 | E5: 1.1.1 | F5: DT34393 | H5: REAR ODS BEAM WEB | I5: 1 | J5: =I5*$J$4 -> 1 | L5: 339 | M5: =L5*J5 -> 339 | N5: Plate | O5: A572 Gr. 50 | R5: 10 | S5: 1022 | T5: 5080
A6: 4 | E6: 1.1.2 | F6: DT34394 | H6: PLATE, OUTER ODS BEAM TOP FLANGE, R2D, PC4100 | I6: 1 | J6: =I6*$J$4 -> 1 | L6: 76 | M6: =L6*J6 -> 76 | N6: Plate | O6: A572 Gr. 50 | R6: 12 | S6: 180 | T6: 4775
A7: 5 | E7: 1.1.3 | F7: DT34395 | H7: PLATE, OUTER BEAM BACK ANGLE CAP, PC4100 | I7: 1 | J7: =I7*$J$4 -> 1 | L7: 9 | M7: =L7*J7 -> 9 | N7: Plate | O7: A572 Gr. 50 | R7: 12 | S7: 180 | T7: 572
A8: 6 | E8: 1.1.4 | F8: DT34315 | H8: PLATE, OUTER FRONT BEAM NOSE CAP, PC4100 | I8: 1 | J8: =I8*$J$4 -> 1 | L8: 8 | M8: =L8*J8 -> 8 | N8: Plate | O8: A36/S275JR/SA 516 GR.70 | R8: 20 | S8: 200 | T8: 324
A9: 7 | E9: 1.1.5 | F9: DT34396 | H9: PLATE, REAR OUTER BEAM ANGLE CAP, PC4100 | I9: 1 | J9: =I9*$J$4 -> 1 | L9: 37 | M9: =L9*J9 -> 37 | N9: Plate | O9: ASTM A572 Gr. 50 / S355JR | R9: 10 | S9: 100 | T9: 4702
A10: 8 | E10: 1.1.6 | F10: DT34397 | H10: PLATE, ANGLE CAP, PC4100 | I10: 1 | J10: =I10*$J$4 -> 1 | L10: 0.8 | M10: =L10*J10 -> 0.8 | N10: Plate | O10: A572 Gr. 50 | R10: 10 | S10: 100 | T10: 191
A11: 9 | E11: 1.1.7 | F11: DT34327 | H11: CATWALK CONNECTION PLATE, PC4100 | I11: 1 | J11: =I11*$J$4 -> 1 | L11: 11.6 | M11: =L11*J11 -> 11.6 | N11: Plate | O11: A36/S275JR/SA 516 GR.70 | R11: 40 | S11: 200 | T11: 200 | AA11: 10
A12: 10 | E12: 1.1.8 | F12: DT34328 | H12: PLATE, CARRIER CONNECTION PLATE GUSSET, PC4100 | I12: 1 | J12: =I12*$J$4 -> 1 | L12: 4 | M12: =L12*J12 -> 4 | N12: Plate | O12: A36/S275JR/SA 516 GR.70 | R12: 25 | S12: 165 | T12: 180
A13: 11 | E13: 1.1.9 | F13: DT34378 | H13: PIPE, 33 OD x 21 ID X 51 L | I13: 4 | J13: =I13*$J$4 -> 4 | L13: =0.2*0.4536 -> 0.09072 | M13: =L13*J13 -> 0.36288 | N13: Pipe | O13: ASTM A106 GR.B | R13: Dia 33 x 6 thk | T13: 51
A14: 12 | E14: 1.1.10 | F14: DT34398 | H14: REAR CATWALK CONNECTION BLOCK, PC4100 | I14: 2 | J14: =I14*$J$4 -> 2 | L14: 19 | M14: =L14*J14 -> 38 | N14: Plate | O14: ASTM A572 Gr. 50 / S355JR | R14: 50 | S14: 220 | T14: 334 | AA14: 45
A15: 13 | E15: 1.1.11 | F15: - | H15: BAR, FLAT, 200 X 20 X 4777 LG | I15: 1 | J15: =I15*$J$4 -> 1 | L15: =R15*S15*T15*0.00000785 -> 149.9978 | M15: =L15*J15 -> 149.9978 | N15: Plate | O15: A36/S275JR/SA 516 GR.70 | R15: 20 | S15: 200 | T15: 4777
A16: 14 | B16: 14 | E16: 1.1.12 | F16: - | H16: BAR, FLAT, 75 x 12 x 381 LG | I16: 2 | J16: =I16*$J$4 -> 2 | L16: =R16*S16*T16*0.00000785 -> 2.691765 | M16: =L16*J16 -> 5.38353 | N16: Plate | O16: A36/S275JR/SA 516 GR.70 | R16: 12 | S16: 75 | T16: 381
A17: 15 | B17: 15 | D17: 1.2 | F17: AY30009 | H17: WELDMENT, CATWALK DS BEAM, R2D, PC4100 | I17: 1 | J17: =I17*$J$3 -> 1 | L17: 667 | M17: =L17*J17 -> 667 | N17: Sub Assy. | O17: SEE BOM
A18: 16 | B18: 16 | E18: 1.2.1 | F18: DT34400 | H18: REAR DS BEAM WEB, R2D, PC4100 | I18: 1 | J18: =I18*$J$17 -> 1 | L18: 321 | M18: =L18*J18 -> 321 | N18: Plate | O18: A572 Gr. 50 | R18: 10 | S18: 1022 | T18: 5080
A19: 17 | B19: 17 | E19: 1.2.2 | F19: DT34401 | H19: PLATE, OUTER BEAM D5 TOP FLANGE, R2D, PC4100 | I19: 1 | J19: =I19*$J$17 -> 1 | L19: 83 | M19: =L19*J19 -> 83 | N19: Plate | O19: A572 Gr. 50 | R19: 12 | S19: 180 | T19: 4775
A20: 18 | B20: 18 | E20: 1.2.3 | F20: DT34395 | H20: PLATE, OUTER BEAM BACK ANGLE CAP, PC4100 | I20: 1 | J20: =I20*$J$17 -> 1 | L20: 9 | M20: =L20*J20 -> 9 | N20: Plate | O20: A572 Gr. 50 | R20: 12 | S20: 180 | T20: 572
A21: 19 | B21: 19 | E21: 1.2.4 | F21: DT34315 | H21: PLATE, OUTER FRONT BEAM NOSE CAP, PC4100 | I21: 1 | J21: =I21*$J$17 -> 1 | L21: 8 | M21: =L21*J21 -> 8 | N21: Plate | O21: A36/S275JR/SA 516 GR.70 | R21: 20 | S21: 200 | T21: 324
A22: 20 | B22: 20 | E22: 1.2.5 | F22: DT34396 | H22: PLATE, REAR OUTER BEAM ANGLE CAP, PC4100 | I22: 1 | J22: =I22*$J$17 -> 1 | L22: 37 | M22: =L22*J22 -> 37 | N22: Plate | O22: ASTM A572 Gr. 50 / S355JR | R22: 10 | S22: 100 | T22: 4702
A23: 21 | B23: 21 | E23: 1.2.6 | F23: DT34397 | H23: PLATE, ANGLE CAP, PC4100 | I23: 1 | J23: =I23*$J$17 -> 1 | L23: 0.8 | M23: =L23*J23 -> 0.8 | N23: Plate | O23: A572 Gr. 50 | R23: 10 | S23: 100 | T23: 191
A24: 22 | B24: 22 | E24: 1.2.7 | F24: DT34327 | H24: CATWALK CONNECTION PLATE, PC4100 | I24: 1 | J24: =I24*$J$17 -> 1 | L24: 11.6 | M24: =L24*J24 -> 11.6 | N24: Plate | O24: A36/S275JR/SA 516 GR.70 | R24: 40 | S24: 200 | T24: 200 | AA24: 10
A25: 23 | B25: 23 | E25: 1.2.8 | F25: DT34328 | H25: PLATE, CARRIER CONNECTION PLATE GUSSET, PC4100 | I25: 1 | J25: =I25*$J$17 -> 1 | L25: 4 | M25: =L25*J25 -> 4 | N25: Plate | O25: A36/S275JR/SA 516 GR.70 | R25: 25 | S25: 165 | T25: 180
A26: 24 | B26: 24 | E26: 1.2.9 | F26: DT34398 | H26: REAR CATWALK CONNECTION BLOCK, PC4100 | I26: 2 | J26: =I26*$J$17 -> 2 | L26: 19 | M26: =L26*J26 -> 38 | N26: Plate | O26: ASTM A572 Gr. 50 / S355JR | R26: 50 | S26: 220 | T26: 334 | AA26: 45
A27: 25 | B27: 25 | E27: 1.2.10 | F27: - | H27: BAR, FLAT, 200 X 20 X 4777 LG | I27: 1 | J27: =I27*$J$17 -> 1 | L27: =R27*S27*T27*0.00000785 -> 149.9978 | M27: =L27*J27 -> 149.9978 | N27: Plate | O27: A36/S275JR/SA 516 GR.70 | R27: 20 | S27: 200 | T27: 4777
A28: 26 | B28: 26 | E28: 1.2.11 | F28: - | H28: PIPE, 1/2" SCH 40 x 1035 LG | I28: 2 | J28: =I28*$J$17 -> 2 | M28: =L28*J28 -> 0 | N28: Pipe | O28: A.S.T.M. A106 GR.B | R28: Dia | T28: 103.5
A29: 27 | B29: 27 | E29: 1.2.12 | F29: - | H29: UNISTRUT, 41.3 x 22.2 x 457 LG | I29: 2 | J29: =I29*$J$17 -> 2 | M29: =L29*J29 -> 0 | N29: BOP Unistruct | O29: G40.21-44W / A572 G50
A30: 28 | B30: 28 | E30: 1.2.13 | F30: DT34399 | H30: PLATE, SAFETY BAR HOLDER, PC4100 | I30: 2 | J30: =I30*$J$17 -> 2 | L30: 2 | M30: =L30*J30 -> 4 | N30: Plate | O30: A572 Gr. 50 | R30: 10 | S30: 210 | T30: 210
A31: 29 | D31: 1.3 | F31: DT34313 | H31: PLATE, ROLL BAR END CAP, PC4100 | I31: 2 | J31: =I31*$J$3 -> 2 | L31: 3.4 | M31: =L31*J31 -> 6.8 | N31: Plate | O31: A572 Gr. 50 | R31: 12 | S31: 200 | T31: 240
A32: 30 | D32: 1.4 | F32: DT34402 | H32: PLATE, BACK MID STOP RIB, PC4100 | I32: 4 | J32: =I32*$J$3 -> 4 | L32: 15 | M32: =L32*J32 -> 60 | N32: Plate | O32: A572 Gr. 50 | R32: 12 | S32: 373 | T32: 789
A33: 31 | D33: 1.5 | F33: DT34403 | H33: PIPE, CABLE ROLL, PC4100 | I33: 2 | J33: =I33*$J$3 -> 2 | L33: 5 | M33: =L33*J33 -> 10 | N33: Sub Assy.
E34: 1.5.1 | H34: PIPE, 4SCH80 X 254 LG | I34: 1 | J34: =I34*$J$33 -> 2 | L34: =L33-L35 -> 4.6516484 | M34: =L34*J34 -> 9.3032968 | N34: Pipe | O34: A.S.T.M. A106 GR.B | R34: Dia 102x8thk | T34: 255 | AA34: 5
E35: 1.5.2 | H35: PLATE, 86 X 86X 6 | I35: 1 | J35: =I35*$J$33 -> 2 | L35: =R35*S35*T35*0.00000785 -> 0.3483516 | M35: =L35*J35 -> 0.6967032 | N35: Plate | O35: A.S.T.M. A106 GR.B | R35: 6 | S35: 86 | T35: 86
A36: 32 | D36: 1.6 | F36: DT34404 | H36: W-BEAM 600 X 220 X 4572 LG | I36: 2 | J36: =I36*$J$3 -> 2 | L36: 498 | M36: =L36*J36 -> 996 | N36: Beam | O36: A992 / A572 | R36: W-BEAM 600 X 220 | T36: 4572
A37: 33 | D37: 1.7 | F37: DT34405 | H37: CARRIER RAIL BOTTOM STIFFNER, DS, PC4100 | I37: 1 | J37: =I37*$J$3 -> 1 | L37: 3 | M37: =L37*J37 -> 3 | N37: Channel | O37: A36/S275JR | R37: UPN80 X 45 | T37: 410
A38: 34 | D38: 1.8 | F38: DT34406 | H38: CARRIER RAIL BOTTOM STIFFNER, ODS, PC4100 | I38: 1 | J38: =I38*$J$3 -> 1 | L38: 3 | M38: =L38*J38 -> 3 | N38: Channel | O38: A36/S275JR | R38: UPN80 X 45 | T38: 410
A39: 35 | D39: 1.9 | F39: - | H39: CHANNEL, UPN200x2198 LG | I39: 7 | J39: =I39*$J$3 -> 7 | L39: =25.3*T39/1000 -> 55.6094 | M39: =L39*J39 -> 389.2658 | N39: Channel | O39: A572 Gr. 50 | R39: UPN 200x75 | T39: 2198 | U39: =25.3*T39/1000 -> 55.6094
A40: 36 | D40: 1.1 | F40: DT34390 | H40: PLATE, BOTTOM PLATE, JUNK BOX, PC4100 | I40: 1 | J40: =I40*$J$3 -> 1 | L40: 27.7 | M40: =L40*J40 -> 27.7 | N40: Plate | O40: ASTM A572 Gr. 50 / A516 Gr.70 / S355JR | R40: 6 | S40: 720 | T40: 819 | Y40: 1 | Z40: R6
...

Sheet RM Details
H1: Assembly | I1: DT34962
A2: RM Details Assy. No | E2: =I1 -> DT34962
A3: Type | B3: Drg. Material | C3: Material | D3: Size (thk) | E3: Net Wet(kg) | F3: Gross Weight (kg) | I3: Column Labels
A4: Plate | B4: ASTM A36/ Q235 | C4: IS 2062 E250 A/BO/BR | D4: 8 | E4: =GETPIVOTDATA("Sum of Total Weight (Kg)",$H$3,"Alt. Material","IS 2062 E250 A/BO/BR","IS Thk (mm)",8) -> 158.59462 | F4: =GETPIVOTDATA("Sum of Gross Wt (kg)",$H$3,"Alt. Material","IS 2062 E250 A/BO/BR","IS Thk (mm)",8) -> 218.0676 | I4: ASTM A514 | K4: IS 2062 E250 A/BO/BR | M4: Total Sum of Total Weight (Kg) | N4: Total Sum of Gross Wt (kg)
A5: Plate | B5: ASTM A514/Q690 | C5: ASTM A514 | D5: 20 | E5: =GETPIVOTDATA("Sum of Total Weight (Kg)",$H$3,"Alt. Material","ASTM A514","IS Thk (mm)",20) -> 8.6184 | F5: =GETPIVOTDATA("Sum of Gross Wt (kg)",$H$3,"Alt. Material","ASTM A514","IS Thk (mm)",20) -> 10.084816 | H5: Row Labels | I5: Sum of Total Weight (Kg) | J5: Sum of Gross Wt (kg) | K5: Sum of Total Weight (Kg) | L5: Sum of Gross Wt (kg)
H6: 8 | K6: 158.59462 | L6: 218.0676 | M6: 158.59462 | N6: 218.0676
H7: 20 | I7: 8.6184 | J7: 10.084816 | M7: 8.6184 | N7: 10.084816
H8: Grand Total | I8: 8.6184 | J8: 10.084816 | K8: 158.59462 | L8: 218.0676 | M8: 167.21302 | N8: 228.15242
A11: RM Details Assy. No | E11: =I11 -> DT34961 | H11: Assembly | I11: DT34961
A12: Type | B12: Drg. Material | C12: Material | D12: Size (thk) | E12: Net Wet(kg) | F12: Gross Weight (kg)
A13: Plate | B13: ASTM A36/ Q235 | C13: IS 2062 E250 A/BO/BR | D13: 8 | E13: =GETPIVOTDATA("Sum of Total Weight (Kg)",$H$13,"IS Thk (mm)",8) -> 177.39731 | F13: =GETPIVOTDATA("Sum of Gross Wt (kg)",$H$13,"IS Thk (mm)",8) -> 243.92131 | I13: Column Labels
A14: Plate | B14: ASTM A514/Q690 | C14: ASTM A514 | D14: 20 | E14: =GETPIVOTDATA("Sum of Total Weight (Kg)",$H$13,"Alt. Material","ASTM A514","IS Thk (mm)",20) -> 8.6184 | F14: =GETPIVOTDATA("Sum of Gross Wt (kg)",$H$13,"Alt. Material","ASTM A514","IS Thk (mm)",20) -> 10.084816 | I14: ASTM A514 | K14: IS 2062 E250 A/BO/BR | M14: Total Sum of Total Weight (Kg) | N14: Total Sum of Gross Wt (kg)
H15: Row Labels | I15: Sum of Total Weight (Kg) | J15: Sum of Gross Wt (kg) | K15: Sum of Total Weight (Kg) | L15: Sum of Gross Wt (kg)
H16: 8 | K16: 177.39731 | L16: 243.92131 | M16: 177.39731 | N16: 243.92131
H17: 20 | I17: 8.6184 | J17: 10.084816 | M17: 8.6184 | N17: 10.084816
H18: Grand Total | I18: 8.6184 | J18: 10.084816 | K18: 177.39731 | L18: 243.92131 | M18: 186.01571 | N18: 254.00612
A21: RM Details Assy. No | E21: =I21 -> DT14062 | H21: Assembly | I21: DT14062
A22: Type | B22: Drg. Material | C22: Material | D22: Size (thk) | E22: Net Wet(kg) | F22: Gross Weight (kg)
A23: Plate | B23: ASTM A36/ Q235 | C23: IS 2062 E250 A/BO/BR | D23: 6 | E23: =GETPIVOTDATA("Sum of Total Weight (Kg)",$H$23,"Alt. Material","IS 2062 E250 A/BO/BR","IS Thk (mm)",6) -> 1.0099502 | F23: =GETPIVOTDATA("Sum of Gross Wt (kg)",$H$23,"Alt. Material","IS 2062 E250 A/BO/BR","IS Thk (mm)",6) -> 1.5870646 | I23: Column Labels
A24: Plate | B24: ASTM A36/ Q235 | C24: IS 2062 E250 A/BO/BR | D24: 20 | E24: =GETPIVOTDATA("Sum of Total Weight (Kg)",$H$23,"Alt. Material","IS 2062 E250 A/BO/BR","IS Thk (mm)",20) -> 179.33084 | F24: =GETPIVOTDATA("Sum of Gross Wt (kg)",$H$23,"Alt. Material","IS 2062 E250 A/BO/BR","IS Thk (mm)",20) -> 253.90306 | I24: 42CrMo4 / EN 19 | K24: IS 2062 E250 A/BO/BR | M24: Total Sum of Total Weight (Kg) | N24: Total Sum of Gross Wt (kg)
A25: Rod | B25: AISI 4140 HTSR | C25: 42CrMo4 / EN 19 | D25: Dia 65 | E25: =GETPIVOTDATA("Sum of Total Weight (Kg)",$H$23,"Alt. Material","42CrMo4 / EN 19","IS Thk (mm)","Dia 65") -> 68.04 | F25: =GETPIVOTDATA("Sum of Gross Wt (kg)",$H$23,"Alt. Material","42CrMo4 / EN 19","IS Thk (mm)","Dia 65") -> 97.405 | H25: Row Labels | I25: Sum of Total Weight (Kg) | J25: Sum of Gross Wt (kg) | K25: Sum of Total Weight (Kg) | L25: Sum of Gross Wt (kg)
H26: 6 | K26: 1.0099502 | L26: 1.5870646 | M26: 1.0099502 | N26: 1.5870646
H27: 20 | K27: 179.33084 | L27: 253.90306 | M27: 179.33084 | N27: 253.90306
H28: Dia 65 | I28: 68.04 | J28: 97.405 | M28: 68.04 | N28: 97.405
H29: Grand Total | I29: 68.04 | J29: 97.405 | K29: 180.34079 | L29: 255.49012 | M29: 248.38079 | N29: 352.89512
A33: RM Details Assy. No | E33: =I33 -> DT14077 | H33: Assembly | I33: DT14077
A34: Type | B34: Drg. Material | C34: Material | D34: Size (thk) | E34: Net Wet(kg) | F34: Gross Weight (kg)
A35: Plate | B35: ASTM A36/ Q235 | C35: IS 2062 E250 A/BO/BR | D35: 6 | E35: =GETPIVOTDATA("Sum of Total Weight (Kg)",$H$35,"Alt. Material","IS 2062 E250 A/BO/BR","IS Thk (mm)",6) -> 0.45775031 | F35: =GETPIVOTDATA("Sum of Gross Wt (kg)",$H$35,"Alt. Material","IS 2062 E250 A/BO/BR","IS Thk (mm)",6) -> 0.71932192 | I35: Column Labels
A36: Plate | B36: ASTM A36/ Q235 | C36: IS 2062 E250 A/BO/BR | D36: 20 | E36: =GETPIVOTDATA("Sum of Total Weight (Kg)",$H$35,"Alt. Material","IS 2062 E250 A/BO/BR","IS Thk (mm)",20) -> 73.946179 | F36: =GETPIVOTDATA("Sum of Gross Wt (kg)",$H$35,"Alt. Material","IS 2062 E250 A/BO/BR","IS Thk (mm)",20) -> 104.51115 | I36: 42CrMo4 / EN 19 | K36: IS 2062 E250 A/BO/BR | M36: Total Sum of Total Weight (Kg) | N36: Total Sum of Gross Wt (kg)
A37: Rod | B37: AISI 4140 HTSR | C37: 42CrMo4 / EN 19 | D37: Dia 65 | E37: =GETPIVOTDATA("Sum of Total Weight (Kg)",$H$35,"Alt. Material","42CrMo4 / EN 19","IS Thk (mm)","Dia 65") -> 30.02832 | F37: =GETPIVOTDATA("Sum of Gross Wt (kg)",$H$35,"Alt. Material","42CrMo4 / EN 19","IS Thk (mm)","Dia 65") -> 41.888 | H37: Row Labels | I37: Sum of Total Weight (Kg) | J37: Sum of Gross Wt (kg) | K37: Sum of Total Weight (Kg) | L37: Sum of Gross Wt (kg)
H38: 6 | K38: 0.45775031 | L38: 0.71932192 | M38: 0.45775031 | N38: 0.71932192
H39: 20 | K39: 73.946179 | L39: 104.51115 | M39: 73.946179 | N39: 104.51115
H40: Dia 65 | I40: 30.02832 | J40: 41.888 | M40: 30.02832 | N40: 41.888
H41: Grand Total | I41: 30.02832 | J41: 41.888 | K41: 74.403929 | L41: 105.23047 | M41: 104.43225 | N41: 147.11847
A44: RM Details Assy. No | E44: =I44 -> DT14647 | H44: Assembly | I44: DT14647
A45: Type | B45: Drg. Material | C45: Material | D45: Size (thk) | E45: Net Wet(kg) | F45: Gross Weight (kg)
A46: Plate | B46: ASTM A514 GR B | C46: ASTM A514 GR B | D46: 25 | E46: =GETPIVOTDATA("Sum of Total Weight (Kg)",$H$46,"Alt. Material","ASTM A514 GR B","IS Thk (mm)",25) -> 17.907126 | F46: =GETPIVOTDATA("Sum of Gross Wt (kg)",$H$46,"Alt. Material","ASTM A514 GR B","IS Thk (mm)",25) -> 26.07144 | I46: Column Labels
A47: Plate | B47: ASTM A514 GR B | C47: ASTM A514 GR B | D47: 32 | E47: =GETPIVOTDATA("Sum of Total Weight (Kg)",$H$46,"Alt. Material","ASTM A514 GR B","IS Thk (mm)",32) -> 105.19452 | F47: =GETPIVOTDATA("Sum of Gross Wt (kg)",$H$46,"Alt. Material","ASTM A514 GR B","IS Thk (mm)",32) -> 120.75737 | I47: 1.7218 (25CrMo4) | K47: ASTM A514 GR B | M47: Total Sum of Total Weight (Kg) | N47: Total Sum of Gross Wt (kg)
A48: Plate | B48: AISI 4130 | C48: 1.7218 (25CrMo4) | D48: Dia 90 | E48: =GETPIVOTDATA("Sum of Total Weight (Kg)",$H$46,"Alt. Material","1.7218 (25CrMo4)","IS Thk (mm)","Dia 90") -> 3.3 | F48: =GETPIVOTDATA("Sum of Gross Wt (kg)",$H$46,"Alt. Material","1.7218 (25CrMo4)","IS Thk (mm)","Dia 90") -> 4.015 | H48: Row Labels | I48: Sum of Total Weight (Kg) | J48: Sum of Gross Wt (kg) | K48: Sum of Total Weight (Kg) | L48: Sum of Gross Wt (kg)
H49: 25 | K49: 17.907126 | L49: 26.07144 | M49: 17.907126 | N49: 26.07144
...

Sheet Welding Details
B2: Assy No. | C2: Item No. | D2: Weld Length | E2: No of Run | F2: No of Places | G2: Total Weld

Sheet Paint Details
H2: Akzonobel
G3: Total Area | H3: ='BOM R2D CatWalk'!AH3 -> 0 | I3: SQM | J3: As per drawing
C4: Paint Details | D4: DFT | E4: Th Coverage (Area m2) | F4: Wastage factor | G4: Actual Coverage (Area m2) | H4: Req Paint (Litre) | I4: Rate of paint | J4: Amount
B5: Primer | C5: Interzinc 42 | D5: 50-75 | E5: =75*7.33/75 -> 7.33 | F5: 0.35 | G5: =E5*(100%-F5) -> 4.7645 | H5: =(1/G5)*$H$3 -> 0 | I5: 1000 | J5: =H5*I5 -> 0 | K5: 1
B6: Paint | C6: Interthane 990 white | D6: 50-75 | E6: =50*11.4/50 -> 11.4 | F6: 0.35 | G6: =E6*(100%-F6) -> 7.41 | H6: =(1/G6)*$H$3 -> 0 | I6: 1000 | J6: =H6*I6 -> 0 | K6: 1
B7: Thinner | H7: =SUM(H5:H6)*0.3 -> 0 | I7: 400 | J7: =H7*I7 -> 0
B8: Total | H8: =SUM(H5:H7) -> 0 | J8: =SUM(J5:J7) -> 0
G9: Paint Applying Cost (Labour and Consuables) | J9: =H3*250 -> 0 | K9: `@250/SQM
B10: Total Paint Cost | J10: =J8+J9 -> 0
B11: Extra paint touch up cost (5%) | I11: 0.05 | J11: =J10*I11 -> 0
B12: Total cost | J12: =J11+J10 -> 0 | K12: =J12/H3 -> #DIV/0!
H17: Akzonobel
G18: Total Area | H18: =H3 -> 0 | J18: SQM | K18: As per drawing
C19: Paint Details | D19: DFT | E19: Th Coverage (Area m2) | F19: Wastage factor | G19: Actual Coverage (Area m2) | H19: Req Paint (Litre) | I19: Minimum Qty | J19: Rate of paint | K19: Amount
B20: Primer | C20: Interzinc 42 | D20: 75 | E20: =75*7.33/D20 -> 7.33 | F20: 0.35 | G20: =E20*(100%-F20) -> 4.7645 | H20: =(1/G20)*$H$3 -> 0 | I20: =H20 -> 0 | J20: 787.5 | K20: =J20*I20 -> 0 | L20: 1
B21: Paint | C21: Interthane 990 white | D21: 75 | E21: =50*13.6/D21 -> 9.0666667 | F21: 0.35 | G21: =E21*(100%-F21) -> 5.8933333 | H21: =(1/G21)*$H$3 -> 0 | I21: 20 | J21: 1200 | K21: =J21*I21 -> 24000 | L21: 1
B22: Thinner | H22: =SUM(H20:H21)*0.3 -> 0 | I22: =H22 -> 0 | J22: 200 | K22: =J22*I22 -> 0
B23: Total | H23: =SUM(H20:H22) -> 0 | K23: =SUM(K20:K22) -> 24000
G24: Paint Applying Cost (Labour and Consuables) | K24: =H18*250 -> 0 | L24: `@250/SQM
B25: Total Paint Cost | K25: =K23+K24 -> 24000
B26: Extra paint touch up cost (5%) | J26: 0.05 | K26: =K25*J26 -> 1200
B27: Total cost | K27: =K26+K25 -> 25200 | L27: =K27/H18 -> #DIV/0!
